Workbook

Sheet 1월
A1: 2026년 1월 계약현황
A2: No. | B2: 성명 | C2: 보증금(원) | D2: 입금일/결제일 | E2: 현금/카드 | F2: 수익금(원) | G2: 최초지급일 | H2: 계좌은행 | I2: 계좌번호 | J2: 예금주 | K2: 주민등록번호 | L2: 핸드폰번호 | M2: 계약만료일 | N2: 비고
A3: 1 | B3: 신영미 | C3: 10000000 | D3: 2026.1.1 | E3: 현금 | F3: 500000 | G3: 2026.3.1 | H3: 농협은행 | I3: 312-013-5476311 | J3: 신영미 | K3: 711124-2394811 | L3: 010-3036-9756 | M3: 2028.12.31
A4: 2 | B4: 최한영 | C4: 30000000 | D4: 2026.1.2 | F4: 2028000 | G4: 2026.3.2 | H4: 농협 | I4: 356-0090-8343-33 | J4: 한동현 | K4: 640325-2229420 | L4: 010-3917-1399 | M4: 2029.1.1
A5: 3 | B5: 김정임 | C5: 10000000 | D5: 2026.1.2 | F5: 500000 | G5: 2026.3.2 | H5: 농협 | I5: 356-0090-8343-33 | J5: 한동현 | K5: 670510-2231121 | L5: 010-9261-8355 | M5: 2029.1.1
A6: 4 | B6: 한유성 | C6: 30000000 | D6: 2026.1.5 | E6: 현금 | F6: 2028000 | G6: 2026.3.5 | H6: 케이뱅크 | I6: 100-11660-33-11 | J6: 곽경호 | K6: 020107-3031438 | L6: 010-4937-8876 | M6: 2028.3.4
A7: 5 | B7: 용서연 | C7: 10000000 | D7: 2026.1.8 | E7: 현금 | F7: 800000 | G7: 2026.3.8 | H7: 농협 | I7: 130012-52-237844 | J7: 용서연 | K7: 740604-2321612 | L7: 010-8285-2846 | M7: 2029.1.7
A8: 6 | B8: 인혜수 | C8: 10000000 | D8: 2026.1.8 | E8: 현금 | F8: 800000 | G8: 2026.3.8 | H8: 농협 | I8: 301-3577-1592-11 | J8: 이하은 | K8: 631008-2806523 | L8: 010-9924-6058 | M8: 2029.1.7
A9: 7 | B9: 이세은 | C9: 10000000 | D9: 2026.1.8 | E9: 현금 | F9: 800000 | G9: 2026.3.8 | H9: 농협 | I9: 301-3577-1592-11 | J9: 이하은 | K9: 740220-2702725 | L9: 010-4742-0224 | M9: 2029.1.7
A10: 8 | B10: 최수호 | C10: 10000000 | D10: 2026.1.9 | E10: 현금(입금자:박명희) | G10: 2026.3.9 | H10: 국민 | I10: 091-24-0230-115 | J10: 박명희 | K10: 060308-3169010 | L10: 010-8785-2273 | M10: 2029.1.8
A11: 9 | B11: 주하민 | C11: 10000000 | D11: 2026.1.10 | E11: 현금 | F11: 800000 | G11: 2026.3.10 | H11: 농협 | I11: 209-12-751764 | J11: 엄혜란 | K11: 020502-3300211 | L11: 010-4506-5645 | M11: 2029.1.9
A12: 10 | B12: 한리나 | C12: 10000000 | D12: 2026.1.10 | E12: 현금 | F12: 800000 | G12: 2026.3.10 | H12: 농협 | I12: 302-1092-2478-81 | J12: 한리나 | K12: 660913-6160013 | L12: 010-3383-6172 | M12: 2029.1.9
A13: 11 | B13: 박란 | C13: 1000000 | D13: 2025.12.11 | E13: 현금 | G13: 2026.3.11 | H13: 국민 | I13: 5825-020104-9618 | J13: 박 란 | K13: 700424-2030810 | L13: 010-4277-0255 | M13: 2028.3.10
C14: 9000000 | D14: 2026.1.11 | E14: 현금
C15: 10000000 | D15: 2026.2.8 | E15: 현금(증액)
A16: 12 | B16: 김준형 | C16: 10000000 | D16: 2026.1.12 | E16: 현금 | F16: 800000 | G16: 2026.3.12 | H16: 국민 | I16: 499402-01-277094 | J16: 김준형 | K16: 831119-1081413 | L16: 010-4933-4918 | M16: 2029.1.11
A17: 한제환 | B17: 정은진 | C17: 10000000 | D17: 2026.1.13 | E17: 현금 | F17: 800000 | G17: 2026.3.13 | H17: 기업 | I17: 140-063753-01-012 | J17: 정은진 | K17: 770406-2149611 | L17: 010-5670-2699 | M17: 2029.1.12
A18: 14 | B18: 김성태 | C18: 10000000 | D18: 2026.1.19 | E18: 현금 | F18: 800000 | G18: 2026.3.19 | H18: 우리 | I18: 1002-636-158538 | J18: 김성태 | K18: 570915-1674532 | L18: 010-6663-4918 | M18: 2029.3.18
A19: 15 | B19: 김도양 | C19: 10000000 | D19: 2026.1.21 | E19: 현금 | F19: 800000 | G19: 2026.3.21 | H19: 농협 | I19: 235084-51-045854 | J19: 김효순 | K19: 650120-2109019 | L19: 010-8273-5355 | M19: 2029.1.20
A20: 16 | B20: 최철영 | C20: 10000000 | D20: 2026.1.21 | E20: 현금(입금자:박명화) | F20: 800000 | G20: 2026.3.21 | H20: 농협 | I20: 235084-51-045854 | J20: 김효순 | K20: 571015-1652843 | L20: 010-4051-5316 | M20: 2029.1.20
A21: 17 | B21: 김효순 | C21: 10000000 | D21: 2026.1.21 | E21: 현금(입금자:박명화) | F21: 800000 | G21: 2026.3.21 | H21: 농협 | I21: 235084-51-045854 | J21: 김효순 | K21: 610324-2390210 | L21: 010-8636-5323 | M21: 2029.1.20 | N21: 입금액 없음(?)
A22: 18 | B22: 김원정 | C22: 10000000 | D22: 2026.1.22 | E22: 현금 | F22: 800000 | G22: 2026.3.22 | H22: 하나 | I22: 8469-1018-128107 | J22: 김원정 | K22: 921122-2083111 | L22: 010-6775-5625 | M22: 2029.1.21
A23: 19 | B23: 조성숙 | C23: 30000000 | D23: 2026.1.26 | E23: 쿱(1/26)전환 | F23: 2028000 | G23: 2026.3.26 | H23: 농협 | I23: 487-02-085217 | J23: 조성숙 | K23: 590101-2041615 | L23: 010-2970-5367 | M23: 2029.1.25
A24: 20 | B24: 안순희 | C24: 10000000 | D24: 2026.1.27 | E24: 현금 | F24: 800000 | G24: 2026.3.27 | H24: 국민 | I24: 212-21-0737-681 | J24: 안순희 | K24: 611213-2256115 | L24: 010-4857-1953 | M24: 2029.1.26
A25: 21 | B25: 이옥현 | C25: 10000000 | D25: 2026.1.27 | E25: 현금 | F25: 800000 | G25: 2026.3.27 | H25: 국민은행 | I25: 292901-04-008958 | J25: 이옥현 | K25: 611211-2797827 | L25: 010-9019-2529 | M25: 2029.1.26 | N25: 이정운(610925-1629751,010-8612-1680)으로부터 양수
A26: 22 | B26: 노영경 | C26: 20000000 | D26: 2026.1.27 | E26: 현금 | F26: 1528000 | G26: 2026.3.27 | H26: 우리 | I26: 1002-634-570005 | J26: 노영경 | K26: 690802-2168021 | L26: 010-5315-9756 | M26: 2029.1.26 | N26: 4/23 4천추가
A27: 23 | B27: 김예원 | C27: 10250000 | D27: 2026.1.26 | E27: 카드 | F27: 800000 | G27: 2026.3.28 | H27: 신한 | I27: 110-433-117452 | J27: 김예원 | K27: 570817-2635211 | L27: 010-8289-0381 | M27: 2029.1.25
A28: 24 | B28: 최윤실 | C28: 10000000 | D28: 2026.1.29 | E28: 현금(증액) | F28: 2400000 | G28: 2026.3.28 | H28: 카카오 | I28: 3333-56-462190 | J28: 최윤실 | K28: 881107-2152010 | L28: 010-7334-5830 | M28: 2029.1.27
C29: 2000000 | D29: 2026.2.26
C30: 18000000 | D30: 2026.2.27
A31: 25 | B31: 박기운 | C31: 10000000 | D31: 2026.1.23 | E31: 현금 | F31: 1528000 | G31: 2026.3.29 | H31: 우체국 | I31: 110-0088-57720 | J31: 박기운 | K31: 600617-1002314 | L31: 010-9461-9350 | M31: 2029.1.28
C32: 10000000 | D32: 2026.2.4 | E32: 현금(증액)
A33: 26 | B33: 이현미 | C33: 1000000 | D33: 2025.12.11 | E33: 현금 | F33: 800000 | G33: 2026.3.29 | H33: 농협 | I33: 351-0308-6589-13 | J33: 안 순 | K33: 770917-2522227 | L33: 010-9678-4025 | M33: 2029.1.28
C34: 9000000 | D34: 2026.1.29 | E34: 현금
A35: 27 | B35: 김정애 | C35: 10000000 | D35: 2026.1.30 | E35: 현금(입금자:진헌주) | F35: 800000 | G35: 2026.3.30 | H35: 농협 | I35: 210-12-252612 | J35: 김정애 | K35: 690410-2330910 | L35: 010-8793-9098 | M35: 2029.1.29
A36: 28 | B36: 정미영 | C36: 10000000 | D36: 2026.1.30 | E36: 현금 | F36: 800000 | G36: 2026.3.30 | H36: 하나 | I36: 278-911442-41407 | J36: 정미영 | K36: 670112-2064022 | L36: 010-5393-9394 | M36: 2029.1.29
B37: 합 계 | C37: =SUM(C3:C36) -> 390250000

Sheet 2월
A1: 2026년 2월 계약현황
A2: No. | B2: 성명 | C2: 보증금(원) | D2: 입금일/결제일 | E2: 현금/카드 | F2: 수익금(원) | G2: 최초지급일 | H2: 계좌은행 | I2: 계좌번호 | J2: 예금주 | K2: 주민등록번호 | L2: 핸드폰번호 | M2: 계약만료일 | N2: 비고
A3: 1 | B3: 구재영 | C3: 10000000 | D3: 2026.2.1 | E3: 현금 | F3: 800000 | G3: 2026.4.1 | H3: 농협 | I3: 352-1407-036993 | J3: 구재영 | K3: 000511-3405611 | L3: 010-3847-1216 | M3: 2029.1.31 | N3: 추천인 : 심선미
C4: 10000000 | D4: 2026.4.1 | E4: 현금(증액) | F4: 800000
A5: 2 | B5: 이현정 | C5: 1000000 | D5: 2026.2.2 | E5: 현금 | F5: 800000 | G5: 2026.4.3 | H5: 신한 | I5: 605-06-611764 | J5: 이현정 | K5: 880201-2168115 | L5: 010-5229-8439 | M5: 2029.2.2
C6: 9000000 | D6: 2026.2.3 | E6: 현금
A7: 3 | B7: 최정윤 | C7: 5000000 | D7: 2026.2.2 | E7: 현금 | F7: 800000 | G7: 2026.4.3 | H7: 농협은행 | I7: 125-12-155653 | J7: 김춘자 | K7: 790813-2163427 | L7: 010-8728-7294 | M7: 2029.2.2 | N7: 계좌변경(카톡)
C8: 5000000 | D8: 2026.2.3 | E8: 현금
A9: 4 | B9: 최삼순 | C9: 19000000 | D9: 2026.2.2 | E9: 현금 | F9: 2028000 | G9: 2026.4.4 | H9: 하나 | I9: 363-810314-52607 | J9: 최삼순 | K9: 510502-2066935 | L9: 010-2937-0970 | M9: 2029.4.3
C10: 11000000 | D10: 2026.2.4 | E10: 현금(증액)
A11: 5 | B11: 기미향 | C11: 10000000 | D11: 2026.2.4 | E11: 현금 | F11: 800000 | G11: 2026.4.4 | H11: 국민 | I11: 161-21-0074-774 | J11: 기미향 | K11: 620223-2261016 | L11: 010-9999-3760 | M11: 2028.2.3
A12: 6 | B12: 김진선 | C12: 10000000 | D12: 2026.2.4 | F12: 800000 | G12: 2026.4.4 | H12: 농협 | I12: 352-0257-7656-13 | J12: 김지섭 | K12: 520826-1025417 | L12: 010-7565-7950 | M12: 2029.2.3
A13: 7 | B13: 손서연 | C13: 10000000 | D13: 2026.2.4 | E13: 현금(에이멘비) | F13: 800000 | G13: 2026.4.4 | H13: 국민 | I13: 460602-01-157376 | J13: 손서연 | K13: 730420-2267710 | L13: 010-5659-5871 | M13: 2029.2.3
A14: 8 | B14: 이명애 | C14: 10000000 | D14: 2026.2.6 | E14: 현금 | G14: 2026.4.6 | H14: 국민 | I14: 811402-04-094276 | J14: 이명애 | K14: 74027-2384414 | L14: 010-4782-9052 | M14: 2029.2.5
C15: 10000000 | D15: 2026.4.3 | E15: 현금(증액)
A16: 9 | B16: 김화정 | C16: 10000000 | D16: 2026.2.6 | E16: 현금 | G16: 2026.4.6 | H16: 국민 | I16: 781-24-0033-627 | J16: 김화정 | K16: 721127-2042043 | L16: 010-2308-6092 | M16: 2029.2.5
A17: 10 | B17: 윤시연 | C17: 10000000 | D17: 2026.2.6 | E17: 현금 | F17: 800000 | G17: 2026.4.6 | H17: 신한 | I17: 318-12-279834 | J17: 윤시연 | K17: 620522-2530514 | L17: 010-3890-2528 | M17: 2029.2.5
A18: 11 | B18: 채사랑 | C18: 10000000 | D18: 2026.2.6 | E18: 현금 | G18: 2026.4.6 | H18: 기업 | I18: 010-2722-1253 | J18: 채사랑 | K18: 801101-2528518 | L18: 010-2722-1253 | M18: 2029.2.5
A19: 12 | B19: 이정순 | C19: 1000000 | D19: 2025.12.31 | E19: 현금 | F19: 1528000 | G19: 2026.4.9 | H19: 농협 | I19: 550-02-048727 | J19: 이정순 | K19: 620504-2794611 | L19: 010-9360-1090 | M19: 2029.1.15
C20: 9000000 | D20: 2026.1.16 | E20: 현금
C21: 10000000 | D21: 2026.2.9 | E21: 현금(증액)
A22: 13 | B22: 박상극 | C22: 1000000 | D22: 2025.11.29 | E22: 현금 | G22: 2026.4.10 | H22: 신한 | I22: 110-009-483826 | J22: 박상극 | K22: 651014-1772911 | L22: 010-3389-2363 | M22: 2029.2.9
C23: 19000000 | D23: 2026.1.19 | E23: 현금
C24: 20000000 | D24: 2026.2.10 | E24: 현금(증액)
A25: 14 | B25: 하주현 | C25: 50000000 | D25: 2026.2.10 | E25: 현금 | G25: 2026.4.10 | H25: 국민 | I25: 740901-01-293331 | J25: 하주현 | K25: 701208-2055626 | L25: 010-7530-5544 | M25: 2029.2.9
A26: 15 | B26: 이표숙 | C26: 10000000 | D26: 2026.2.10 | E26: 현금 | F26: 500000 | G26: 2026.4.10 | H26: 하나 | I26: 436-910101-08607 | J26: 이표숙 | K26: 630526-2464913 | L26: 010-7313-5240 | M26: 2029.2.9
A27: 16 | B27: 고임순 | C27: 10000000 | D27: 2026.2.10 | E27: 현금 | F27: 800000 | G27: 2026.4.10 | H27: 국민 | I27: 492301-01-192856 | J27: 고임순 | K27: 610902-2025337 | L27: 010-4007-9533 | M27: 2029.2.9
A28: 17 | B28: 정혜교 | C28: 10000000 | D28: 2026.2.11 | E28: 현금 | F28: 500000 | G28: 2026.4.11 | H28: 농협 | I28: 211023-56-081416 | J28: 김영희 | K28: 001121-4216022 | L28: 010-3532-5816 | M28: 2029.2.10
A29: 18 | B29: 정혜나 | C29: 10000000 | D29: 2026.2.11 | E29: 현금 | F29: 500000 | G29: 2026.4.11 | H29: 농협 | I29: 211023-56-081416 | J29: 김영희 | K29: 970519-2216016 | L29: 010-7398-5816 | M29: 2029.2.10
A30: 19 | B30: 김은숙 | C30: 10000000 | D30: 2026.2.13 | E30: 현금 | F30: 800000 | G30: 2026.4.13 | H30: 신한 | I30: 100-253-112763 | J30: 김은숙 | K30: 660817-6780178 | L30: 010-4187-5531 | M30: 2029.2.12
A31: 20 | B31: 신채운 | C31: 10000000 | D31: 2026.2.14 | E31: 현금 | F31: 800000 | G31: 2026.4.14 | H31: 하나 | I31: 436-910045-48208 | J31: 신채운 | K31: 640112-2670710 | L31: 010-6889-6899 | M31: 2029.2.13
A32: 21 | B32: 조길자 | C32: 10000000 | D32: 2026.2.14 | E32: 현금/카드 | F32: 800000 | G32: 2026.4.14 | H32: 우체국 | I32: 013-656-02-251533 | J32: 조길자 | K32: 600720-2455946 | L32: 010-5682-0979 | M32: 2029.2.13
A33: 22 | B33: 나성우 | C33: 10000000 | D33: 2026.2.14 | E33: 현금 | F33: 800000 | G33: 2026.4.14 | H33: 우리 | I33: 1002-758-675462 | N33: 계약서 없음
A34: 23 | B34: 백서경 | C34: 10000000 | D34: 2026.2.14 | E34: 현금 | F34: 800000 | G34: 2026.4.14 | H34: 새마을 | I34: 0807-09-006407-9 | J34: 최유진 | K34: 620302-2458320 | L34: 010-3364-6259 | M34: 2029.2.13 | N34: 계좌변경
A35: 24 | B35: 나호윤 | C35: 10000000 | D35: 2026.2.14 | E35: 현금 | F35: 800000 | G35: 2026.4.14 | H35: 국민 | I35: 543001-01-178604 | J35: 이보령 | K35: 930208-1072518 | L35: 010-3547-3850 | M35: 2029.2.13
A36: 25 | B36: 이보령 | C36: 10000000 | D36: 2026.2.14 | E36: 현금 | F36: 800000 | G36: 2026.4.14 | H36: 국민 | I36: 543001-01-178604 | J36: 이보령 | K36: 651124-2120630 | L36: 010-7303-3827 | M36: 2029.2.13
A37: 26 | B37: 신승애 | C37: 10000000 | D37: 2026.1.31 | E37: 현금 | G37: 2026.4.15 | H37: 신한 | I37: 110-456-724722 | J37: 신승애 | K37: 64110- | L37: 010-6642-1368 | M37: 2029.1.30
C38: 20000000 | D38: 2026.2.25 | E38: 현금(증액)
A39: 27 | B39: 서채연 | C39: 10000000 | D39: 2026.2.15 | E39: 현금 | F39: 800000 | G39: 2026.4.15 | H39: 신한 | I39: 110-214-814507 | J39: 서채연 | K39: 551222-2005414 | L39: 010-6707-9414 | M39: 2029.2.14
A40: 28 | B40: 조정애 | C40: 10000000 | D40: 2026.2.16 | E40: 현금(입금자:정선훈) | F40: 800000 | G40: 2026.4.16 | H40: 우리 | I40: 1002-037-513462 | J40: 조정애 | K40: 640826-2037421 | L40: 010-4145-3004
...

Sheet 3월
A1: 2026년 3월 계약현황
A2: 추천인 | B2: 성명 | C2: 보증금(원) | D2: 입금일/결제일 | E2: 현금/카드 | F2: 수익금(원) | G2: 최초지급일 | H2: 계좌은행 | I2: 계좌번호 | J2: 예금주 | K2: 주민등록번호 | L2: 핸드폰번호 | M2: 계약만료일 | N2: 비고
A3: 양은호 | B3: 신정환 | C3: 10000000 | D3: 46082 | E3: 현금 | F3: 800000 | G3: =EDATE(D3,2) -> 46143 | H3: 씨티은행 | I3: 421-51330-267 | J3: 나유경 | K3: 070921-3046419 | L3: 010-3600-6943 | M3: =EDATE(D3,36)-1 -> 47177 | N3: (내용확인-카톡)
A4: 경기련 | B4: 경민호 | C4: 10000000 | D4: 46083 | E4: 현금 | F4: 800000 | G4: =EDATE(D4,2) -> 46144 | H4: 카카오뱅크 | I4: 3333-34-7252756 | J4: 경기련 | K4: 720102-1109325 | L4: 010-7644-5049 | M4: =EDATE(D4,36)-1 -> 47178
B5: 강희숙 | C5: 10000000 | D5: 46084 | E5: 현금 | F5: 800000 | G5: =IF(D5>0,EDATE(D5,2),"") -> 46145 | H5: 우리은행 | I5: 1002-738-720421 | J5: 강희숙 | K5: 550124-2144011 | L5: 010-7134-5784 | M5: =IF(D5>0,EDATE(D5,36)-1,"") -> 47179
A6: 한제환 | B6: 이영희 | C6: 10000000 | D6: 46084 | E6: 현금 | F6: 800000 | G6: =IF(D6>0,EDATE(D6,2),"") -> 46145 | H6: 하나은행 | I6: 367-910374-17107 | J6: 노현주 | K6: 560110-2030517 | L6: 010-7734-1234 | M6: =IF(D6>0,EDATE(D6,36)-1,"") -> 47179
A7: 한제환 | B7: 김사승 | C7: 10000000 | D7: 46085 | E7: 현금 | F7: 800000 | G7: =IF(D7>0,EDATE(D7,2),"") -> 46146 | H7: 시티은행 | I7: 445-08484-265-01 | J7: 김사승 | K7: 590321-1249913 | L7: 010-4397-8408 | M7: =IF(D7>0,EDATE(D7,36)-1,"") -> 47180
B8: 류희자 | C8: 10000000 | D8: 46085 | E8: 카드/현금 | F8: 800000 | G8: =IF(D8>0,EDATE(D8,2),"") -> 46146 | H8: 국민은행 | I8: 825-24-0204-011 | J8: 류희자 | K8: 550226-2241313 | L8: 010-8654-7450 | M8: =IF(D8>0,EDATE(D8,36)-1,"") -> 47180
A9: 신재희 | B9: 이은정 | C9: 10000000 | D9: 46085 | F9: 500000 | G9: =IF(D9>0,EDATE(D9,2),"") -> 46146 | H9: 신한은행 | I9: 110-231-120735 | J9: 이은정 | K9: 670822-2056224 | L9: 010-3218-1738 | M9: =IF(D9>0,EDATE(D9,36)-1,"") -> 47180 | N9: 금액정보확인
A10: 안순희 | B10: 김춘봉 | C10: 10000000 | D10: 46086 | E10: 현금 | F10: 800000 | G10: =IF(D10>0,EDATE(D10,2),"") -> 46147 | H10: 농협은행 | I10: 302-1787-7879-31 | J10: 김영순 | K10: 470629-2020614 | L10: 010-6280-1703 | M10: =IF(D10>0,EDATE(D10,36)-1,"") -> 47181
B11: 박정희 | C11: 10000000 | D11: 46086 | E11: 현금 | F11: 800000 | G11: =IF(D11>0,EDATE(D11,2),"") -> 46147 | H11: 농협은행 | I11: 302-1195-2579-41 | J11: =IF(B11>0,B11,"") -> 박정희 | K11: 560115-2155131 | L11: 010-7216-3678 | M11: =IF(D11>0,EDATE(D11,36)-1,"") -> 47181
B12: 홍경미 | C12: 10000000 | D12: 46086 | E12: 현금 | F12: 800000 | G12: =IF(D12>0,EDATE(D12,2),"") -> 46147 | H12: 농협은행 | I12: 356-0782-6434-13 | J12: 이영원 | K12: 610227-2228812 | L12: 010-8297-8657 | M12: =IF(D12>0,EDATE(D12,36)-1,"") -> 47181
A13: 강장용 | B13: 이향순 | C13: 30000000 | D13: 46086 | E13: 현금 | G13: =IF(D13>0,EDATE(D13,2),"") -> 46147 | H13: 농협은행 | I13: 352-1320-5515-13 | J13: 이윤미 | K13: 571011-2522616 | L13: 010-4718-2525 | M13: =IF(D13>0,EDATE(D13,36)-1,"") -> 47181
A14: 한제환 | B14: 김영돈 | C14: 60000000 | D14: 46086 | E14: 현금 | F14: 4056000 | G14: =IF(D14>0,EDATE(D14,2),"") -> 46147 | H14: 신한은행 | I14: 110-486-382256 | J14: =IF(B14>0,B14,"") -> 김영돈 | K14: 781126-1046718 | L14: 010-9454-5285 | M14: =IF(D14>0,EDATE(D14,36)-1,"") -> 47181
A15: 박기운 | B15: 문진천 | C15: 20000000 | D15: 46086 | E15: 현금 | F15: 1528000 | G15: =IF(D15>0,EDATE(D15,2),"") -> 46147 | H15: 농협은행 | I15: 352-1158-787713 | J15: =IF(B15>0,B15,"") -> 문진천 | K15: 630520-2715614 | L15: 010-6433-7835 | M15: =IF(D15>0,EDATE(D15,36)-1,"") -> 47181
A16: 박정란 | B16: 염종수 | C16: 10000000 | D16: 46087 | E16: 현금 | F16: 800000 | G16: =IF(D16>0,EDATE(D16,2),"") -> 46148 | H16: 농협은행 | I16: 352-2327-3606-83 | J16: =IF(B16>0,B16,"") -> 염종수 | K16: 840616-1025111 | L16: 010-3207-1325 | M16: =IF(D16>0,EDATE(D16,36)-1,"") -> 47182
B17: 구성회 | C17: 10000000 | D17: 46087 | E17: 현금 | F17: 800000 | G17: =IF(D17>0,EDATE(D17,2),"") -> 46148 | H17: 농협은행 | I17: 351-1331-4641-93 | J17: =IF(B17>0,B17,"") -> 구성회 | K17: 590210-1036511 | L17: 010-5488-3177 | M17: =IF(D17>0,EDATE(D17,36)-1,"") -> 47182
B18: 김형섭 | C18: 10000000 | D18: 46084 | E18: 카드 | F18: 800000 | G18: =IF(D18>0,EDATE(D18,2),"")+3 -> 46148 | H18: 우리은행 | I18: 1002-534-998012 | J18: =IF(B18>0,B18,"") -> 김형섭 | K18: 750921-1019616 | L18: 010-8074-0381 | M18: =IF(D18>0,EDATE(D18,36)-1,"") -> 47179
B19: 김현옥 | C19: 10000000 | D19: 46084 | E19: 카드 | F19: 800000 | G19: =IF(D19>0,EDATE(D19,2),"")+3 -> 46148 | H19: 하나은행 | I19: 010-20735340-407 | J19: =IF(B19>0,B19,"") -> 김현옥 | K19: 691205-2472229 | L19: 010-7172-5340 | M19: =IF(D19>0,EDATE(D19,36)-1,"") -> 47179
A20: 한제환 | B20: 박성철 | C20: 10000000 | D20: 46088 | E20: 카드 | F20: 800000 | G20: =IF(D20>0,EDATE(D20,2),"") -> 46149 | H20: 우리은행 | I20: 1002-130-791256 | J20: =IF(B20>0,B20,"") -> 박성철 | K20: 750424-1659411 | L20: 010-4152-0191 | M20: =IF(D20>0,EDATE(D20,36)-1,"") -> 47183
A21: 한제환 | B21: 강성철 | C21: 30000000 | D21: 46089 | E21: 현금 | F21: 2028000 | G21: =IF(D21>0,EDATE(D21,2),"") -> 46150 | H21: 국민은행 | I21: 822402-04-248167 | J21: =IF(B21>0,B21,"") -> 강성철 | K21: 700725-1006821 | L21: 010-7291-7991 | M21: =IF(D21>0,EDATE(D21,36)-1,"") -> 47184 | N21: 3천만원 증액계약없음
B22: 박세영 | C22: 20000000 | D22: 46089 | E22: 현금 | F22: 1528000 | G22: =IF(D22>0,EDATE(D22,2),"") -> 46150 | H22: 기업은행 | I22: 208-127561-01-015 | J22: =IF(B22>0,B22,"") -> 박세영 | K22: 611204-1029916 | L22: 010-6342-8461 | M22: =IF(D22>0,EDATE(D22,36)-1,"") -> 47184
B23: 김양숙 | C23: 10000000 | D23: 46090 | E23: 현금 | F23: 800000 | G23: =IF(D23>0,EDATE(D23,2),"") -> 46151 | H23: 우리은행 | I23: 1002-833-448110 | J23: =IF(B23>0,B23,"") -> 김양숙 | K23: 591104-2665811 | L23: 010-8465-7237 | M23: =IF(D23>0,EDATE(D23,36)-1,"") -> 47185
B24: 신화순 | C24: 10000000 | D24: 46090 | E24: 현금 | F24: 800000 | G24: =IF(D24>0,EDATE(D24,2),"") -> 46151 | H24: 우리은행 | I24: 060-21-0124-590 | J24: =IF(B24>0,B24,"") -> 신화순 | K24: 550717-2471414 | L24: 010-5300-0681 | M24: =IF(D24>0,EDATE(D24,36)-1,"") -> 47185 | N24: 현금/카드 확인
A25: 민복돌 | B25: 박진숙 | C25: 10000000 | D25: 46090 | E25: 현금 | F25: 500000 | G25: =IF(D25>0,EDATE(D25,2),"") -> 46151 | H25: 산림조합 | I25: 113-12-0066093 | J25: =IF(B25>0,B25,"") -> 박진숙 | K25: 690311-2247712 | L25: 010-7412-5278 | M25: =IF(D25>0,EDATE(D25,36)-1,"") -> 47185
B26: 김현숙 | C26: 60000000 | D26: 46091 | E26: 현금 | F26: 4056000 | G26: =IF(D26>0,EDATE(D26,2),"") -> 46152 | H26: 우리은행 | I26: 191-346545-02-007 | J26: =IF(B26>0,B26,"") -> 김현숙 | K26: 490219-2066811 | L26: 010-4131-0269 | M26: =IF(D26>0,EDATE(D26,36)-1,"") -> 47186
B27: 김성원 | C27: 10000000 | D27: 46091 | E27: 현금 | F27: 800000 | G27: =IF(D27>0,EDATE(D27,2),"") -> 46152 | H27: 우리은행 | I27: 1002-833-448110 | J27: =IF(B27>0,B27,"") -> 김성원 | K27: 850110-1408720 | L27: 010-7932-7237 | M27: =IF(D27>0,EDATE(D27,36)-1,"") -> 47186 | N27: 현금/카드 확인
B28: 박관규 | C28: 10000000 | D28: 46091 | E28: 현금 | G28: =IF(D28>0,EDATE(D28,2),"") -> 46152 | H28: 국민은행 | I28: 827-21-0550-956 | J28: =IF(B28>0,B28,"") -> 박관규 | K28: 710225-1122633 | L28: 010-3779-0256 | M28: =IF(D28>0,EDATE(D28,36)-1,"") -> 47186
B29: 박지성 | C29: 60000000 | D29: 46091 | E29: 현금 | F29: 3000000 | G29: =IF(D29>0,EDATE(D29,2),"") -> 46152 | H29: 우리은행 | I29: 337-410842-02-001 | J29: =IF(B29>0,B29,"") -> 박지성 | K29: 890515-1029919 | L29: 010-3123-3500 | M29: =IF(D29>0,EDATE(D29,36)-1,"") -> 47186 | N29: 계약내용확인
B30: 김은정 | C30: 10000000 | D30: 46092 | G30: =IF(D30>0,EDATE(D30,2),"") -> 46153 | H30: 농협은행 | I30: 302-1822-5517-11 | J30: =IF(B30>0,B30,"") -> 김은정 | K30: 791203-2122912 | L30: 010-7686-0955 | M30: =IF(D30>0,EDATE(D30,36)-1,"") -> 47187 | N30: 현금/카드 확인
B31: 장복순 | C31: 10000000 | D31: 46093 | E31: 현금 | F31: 800000 | G31: =IF(D31>0,EDATE(D31,2),"") -> 46154 | H31: 신한은행 | I31: 326-04-626403 | J31: =IF(B31>0,B31,"") -> 장복순 | K31: 660525-2522211 | L31: 010-7721-1767 | M31: =IF(D31>0,EDATE(D31,36)-1,"") -> 47188
B32: 심건희 | C32: 10000000 | D32: 46093 | E32: 현금 | G32: =IF(D32>0,EDATE(D32,2),"") -> 46154 | H32: 농협은행 | I32: 501021-52-136575 | J32: 김은철 | K32: 620116-2548818 | L32: 010-6585-9986 | M32: =IF(D32>0,EDATE(D32,36)-1,"") -> 47188
B33: 추남수 | C33: 10000000 | D33: 46093 | E33: 현금 | F33: 800000 | G33: =IF(D33>0,EDATE(D33,2),"") -> 46154 | H33: 농협은행 | I33: 352-8571-2353-33 | J33: =IF(B33>0,B33,"") -> 추남수 | K33: 631116-1650618 | L33: 010-8571-2353 | M33: =IF(D33>0,EDATE(D33,36)-1,"") -> 47188
A34: 한제환 | B34: 박영균 | C34: 10000000 | D34: 46093 | E34: 현금 | F34: 800000 | G34: =IF(D34>0,EDATE(D34,2),"") -> 46154 | H34: 국민은행 | I34: 265-24-0052666 | J34: =IF(B34>0,B34,"") -> 박영균 | K34: 741117-1231743 | L34: 010-9642-1118 | M34: =IF(D34>0,EDATE(D34,36)-1,"") -> 47188
A35: 신재희 | B35: 박경아 | C35: 10000000 | D35: 46093 | E35: 현금 | F35: 500000 | G35: =IF(D35>0,EDATE(D35,2),"") -> 46154 | H35: 하나은행 | I35: 743-910198-36807 | J35: =IF(B35>0,B35,"") -> 박경아 | K35: 730609-2221221 | L35: 010-9623-5666 | M35: =IF(D35>0,EDATE(D35,36)-1,"") -> 47188
A36: 한제환 | B36: 김기영 | C36: 20000000 | D36: 46091 | E36: 카드 | F36: 1528000 | G36: =IF(D36>0,EDATE(D36,2),"")+3 -> 46155 | H36: 우리은행 | I36: 1002-544-828493 | J36: =IF(B36>0,B36,"") -> 김기영 | K36: 671123-1041512 | L36: 010-3770-7245 | M36: =IF(D36>0,EDATE(D36,36)-1,"") -> 47186
B37: 김행정 | C37: 10000000 | D37: 46094 | E37: 카드/현금 | F37: 800000 | G37: =IF(D37>0,EDATE(D37,2),"") -> 46155 | H37: 국민은행 | I37: 805-21-0314304 | J37: =IF(B37>0,B37,"") -> 김행정 | K37: 710526-2068123 | L37: 010-76079229 | M37: =IF(D37>0,EDATE(D37,36)-1,"") -> 47189
B38: 이재성 | C38: 10000000 | D38: 46095 | E38: 카드 | G38: =IF(D38>0,EDATE(D38,2),"") -> 46156 | H38: 카카오뱅크 | I38: 3333-21-2944218 | J38: =IF(B38>0,B38,"") -> 이재성 | K38: 020111-3171318 | L38: 010-5550-1772 | M38: =IF(D38>0,EDATE(D38,36)-1,"") -> 47190
B39: 김태영 | C39: 20000000 | D39: 46095 | E39: 현금 | F39: 1528000 | G39: =IF(D39>0,EDATE(D39,2),"") -> 46156 | H39: 농협은행 | I39: 627-12-231360 | J39: =IF(B39>0,B39,"") -> 김태영 | K39: 640210-2490411 | L39: 010-4627-8912 | M39: =IF(D39>0,EDATE(D39,36)-1,"") -> 47190
B40: 이기전 | C40: 10000000 | D40: 46095 | E40: 현금 | F40: 800000 | G40: =IF(D40>0,EDATE(D40,2),"") -> 46156 | H40: 기업은행 | I40: 142-116755-01-014 | J40: =IF(B40>0,B40,"") -> 이기전 | K40: 610619-1067132 | L40: 010-5001-0365 | M40: =IF(D40>0,EDATE(D40,36)-1,"") -> 47190
...

Sheet 4월
A1: 2026년 4월 계약현황
A2: 추천인 | B2: 성명 | C2: 보증금(원) | D2: 입금일/결제일 | E2: 현금/카드 | F2: 수익금(원) | G2: 최초지급일 | H2: 계좌은행 | I2: 계좌번호 | J2: 예금주 | K2: 주민등록번호 | L2: 핸드폰번호 | M2: 계약만료일 | N2: 비고
B3: 강유나 | C3: 10000000 | D3: 46115 | E3: 카드/현금 | F3: 800000 | G3: =IF(D3>0,EDATE(D3,2),"") -> 46176 | H3: 농협은행 | I3: 302-0865-2540-21 | J3: =IF(B3>0,B3,"") -> 강유나 | K3: 040207-4238713 | L3: 010-6851-5709 | M3: =IF(D3>0,EDATE(D3,36)-1,"") -> 47210
B4: 김용규 | D4: 46114 | E4: 현금 | G4: =IF(D4>0,EDATE(D4,2),"") -> 46175 | H4: 우리은행 | I4: 1002-942-593052 | J4: =IF(B4>0,B4,"") -> 김용규 | K4: 720604-1548317 | L4: 010-3152-3764 | M4: =IF(D4>0,EDATE(D4,36)-1,"") -> 47209
B5: 유경후 | C5: 10000000 | D5: 46114 | E5: 현금 | F5: 800000 | G5: =IF(D5>0,EDATE(D5,2),"") -> 46175 | H5: 우리은행 | I5: 1002-942-593052 | J5: 유경주 | K5: 690128-2547910 | L5: 010-3152-3764 | M5: =IF(D5>0,EDATE(D5,36)-1,"") -> 47209
B6: 김주성 | C6: 20000000 | D6: 46114 | E6: 현금 | G6: =IF(D6>0,EDATE(D6,2),"") -> 46175 | H6: 우리은행 | I6: 1002-942-593052 | J6: 유경주 | K6: 080318-3496920 | L6: 010-3152-3764 | M6: =IF(D6>0,EDATE(D6,36)-1,"") -> 47209
B7: 조은영 | C7: 10000000 | D7: 46113 | E7: 현금 | F7: 800000 | G7: =IF(D7>0,EDATE(D7,2),"") -> 46174 | H7: 농협은행 | I7: 356-1499-5675-33 | J7: =IF(B7>0,B7,"") -> 조은영 | K7: 810125-2093925 | L7: 010-5106-9098 | M7: =IF(D7>0,EDATE(D7,36)-1,"") -> 47208 | N7: 계약서 2건 확인
B8: 김지선 | C8: 10000000 | D8: 46113 | E8: 현금 | F8: 800000 | G8: =IF(D8>0,EDATE(D8,2),"") -> 46174 | H8: 농협은행 | I8: 356-1446-1396-13 | J8: 최영하 | K8: 900808-201110 | L8: 010-3436-4407 | M8: =IF(D8>0,EDATE(D8,36)-1,"") -> 47208 | N8: 주민번호확인
B9: 최민주 | C9: 10000000 | D9: 46113 | E9: 현금 | F9: 800000 | G9: =IF(D9>0,EDATE(D9,2),"") -> 46174 | H9: 농협은행 | I9: 356-1446-1396-13 | J9: 최영하 | K9: 870209-1152021 | L9: 010-8950-5833 | M9: =IF(D9>0,EDATE(D9,36)-1,"") -> 47208
B10: 이옥경 | C10: 10000000 | D10: 46113 | E10: 현금 | F10: 500000 | G10: =IF(D10>0,EDATE(D10,2),"") -> 46174 | H10: 하나은행 | I10: 842-910274-60207 | J10: =IF(B10>0,B10,"") -> 이옥경 | K10: 690325-2474216 | L10: 010-6218-9613 | M10: =IF(D10>0,EDATE(D10,36)-1,"") -> 47208
B11: 윤현경 | C11: 10000000 | D11: 46115 | E11: 현금 | F11: 800000 | G11: =IF(D11>0,EDATE(D11,2),"") -> 46176 | H11: 제주은행 | I11: 19-02-304181 | J11: =IF(B11>0,B11,"") -> 윤현경 | K11: 950311-2932716 | L11: 010-9695-8749 | M11: =IF(D11>0,EDATE(D11,36)-1,"") -> 47210
B12: 김성만 | C12: 20000000 | D12: 46118 | E12: 현금 | G12: =IF(D12>0,EDATE(D12,2),"") -> 46179 | H12: 신한은행 | I12: 110-516-511430 | J12: =IF(B12>0,B12,"") -> 김성만 | K12: 570607-1017114 | L12: 010-7270-7613 | M12: =IF(D12>0,EDATE(D12,36)-1,"") -> 47213
A13: 김보은 | B13: 권은경 | C13: 10000000 | D13: 46118 | E13: 현금 | F13: 800000 | G13: =IF(D13>0,EDATE(D13,2),"") -> 46179 | H13: 국민은행 | I13: 384702-04-003448 | J13: =IF(B13>0,B13,"") -> 권은경 | K13: 700511-2469411 | L13: 010-8978-5412 | M13: =IF(D13>0,EDATE(D13,36)-1,"") -> 47213
B14: 이은영 | C14: 10000000 | D14: 46118 | E14: 현금 | G14: =IF(D14>0,EDATE(D14,2),"") -> 46179 | H14: 국민은행 | I14: 011-21-0351-355 | J14: =IF(B14>0,B14,"") -> 이은영 | K14: 630419-2538312 | L14: 010-3732-9807 | M14: =IF(D14>0,EDATE(D14,36)-1,"") -> 47213
A15: 김보은 | B15: 김혜람 | C15: 20000000 | D15: 46118 | E15: 현금 | F15: 1528000 | G15: =IF(D15>0,EDATE(D15,2),"") -> 46179 | H15: 토스은행 | I15: 1001-7743-5377 | J15: =IF(B15>0,B15,"") -> 김혜람 | K15: 750826-2010921 | L15: 010-9178-0750 | M15: =IF(D15>0,EDATE(D15,36)-1,"") -> 47213
B16: 이정하 | C16: 10000000 | D16: 46119 | E16: 현금 | F16: 800000 | G16: =IF(D16>0,EDATE(D16,2),"") -> 46180 | H16: 신한은행 | I16: 110-384-323810 | J16: =IF(B16>0,B16,"") -> 이정하 | K16: 640429-2551117 | L16: 010-3905-3988 | M16: =IF(D16>0,EDATE(D16,36)-1,"") -> 47214
B17: 김응호 | C17: 10000000 | D17: 46123 | E17: 현금 | F17: 800000 | G17: =IF(D17>0,EDATE(D17,2),"") -> 46184 | H17: 국민은행 | I17: 543001-01-178604 | J17: 이보령 | K17: 570428-1237137 | L17: 010-7142-0690 | M17: =IF(D17>0,EDATE(D17,36)-1,"") -> 47218
B18: 오경철 | D18: 46123 | G18: =IF(D18>0,EDATE(D18,2),"") -> 46184 | H18: 국민은행 | I18: 543001-01-178604 | J18: 이보령 | K18: 530820-1683119 | L18: 010-4443-2021 | M18: =IF(D18>0,EDATE(D18,36)-1,"") -> 47218 | N18: 입금정보확인
B19: 최인숙 | D19: 46123 | G19: =IF(D19>0,EDATE(D19,2),"") -> 46184 | H19: 국민은행 | I19: 543001-01-178604 | J19: 이보령 | K19: 560712-2229614 | L19: 010-3388-2272 | M19: =IF(D19>0,EDATE(D19,36)-1,"") -> 47218 | N19: 입금정보확인
B20: 김대연 | D20: 46123 | G20: =IF(D20>0,EDATE(D20,2),"") -> 46184 | H20: 국민은행 | I20: 543001-01-178604 | J20: 이보령 | K20: 811007-1702811 | L20: 010-5469-0579 | M20: =IF(D20>0,EDATE(D20,36)-1,"") -> 47218 | N20: 입금정보확인
B21: 김미원 | D21: 46123 | G21: =IF(D21>0,EDATE(D21,2),"") -> 46184 | H21: 국민은행 | I21: 543001-01-178604 | J21: 이보령 | K21: 640819-2644013 | L21: 010-9697-4379 | M21: =IF(D21>0,EDATE(D21,36)-1,"") -> 47218 | N21: 입금정보확인
B22: 고정복 | C22: 10000000 | D22: 46113 | E22: 카드 | F22: 800000 | G22: =IF(D22>0,EDATE(D22,2),"") -> 46174 | H22: 우체국은행 | I22: 013912-02-346670 | J22: 백서경 | K22: 590724-2559411 | L22: 010-2221-4734 | M22: =IF(D22>0,EDATE(D22,36)-1,"") -> 47208
B23: 김미영 | C23: 10000000 | D23: 46116 | E23: 현금 | F23: 800000 | G23: =IF(D23>0,EDATE(D23,2),"") -> 46177 | H23: 수협은행 | I23: 001-02-599-750-9 | J23: =IF(B23>0,B23,"") -> 김미영 | K23: 620115-2474412 | L23: 010-2599-7509 | M23: =IF(D23>0,EDATE(D23,36)-1,"") -> 47211
B24: 윤철홍 | C24: 10000000 | D24: 46115 | E24: 현금 | F24: 800000 | G24: =IF(D24>0,EDATE(D24,2),"") -> 46176 | H24: 농협은행 | I24: 980-02-071879 | J24: =IF(B24>0,B24,"") -> 윤철홍 | K24: 651006-1932712 | L24: 010-3077-3900 | M24: =IF(D24>0,EDATE(D24,36)-1,"") -> 47210
B25: 박준형 | C25: 10000000 | D25: 46115 | E25: 현금 | F25: 800000 | G25: =IF(D25>0,EDATE(D25,2),"") -> 46176 | H25: 우리은행 | I25: 1002-743-275072 | J25: =IF(B25>0,B25,"") -> 박준형 | K25: 880618-1253710 | L25: 010-4890-3551 | M25: =IF(D25>0,EDATE(D25,36)-1,"") -> 47210
B26: 임혜경 | C26: 10000000 | D26: 46115 | E26: 현금 | F26: 800000 | G26: =IF(D26>0,EDATE(D26,2),"") -> 46176 | H26: 농협은행 | I26: 241027-56-102170 | J26: =IF(B26>0,B26,"") -> 임혜경 | K26: 690913-2122911 | L26: 010-4720-7440 | M26: =IF(D26>0,EDATE(D26,36)-1,"") -> 47210
B27: 염보라 | C27: 10000000 | D27: 46115 | E27: 현금 | F27: 800000 | G27: =IF(D27>0,EDATE(D27,2),"") -> 46176 | H27: 토스은행 | I27: 1000-5457-2704 | J27: =IF(B27>0,B27,"") -> 염보라 | K27: 890329-2009817 | L27: 010-4476-3551 | M27: =IF(D27>0,EDATE(D27,36)-1,"") -> 47210
B28: 이해린 | C28: 20000000 | D28: 46126 | E28: 카드/현금 | G28: =IF(D28>0,EDATE(D28,2),"") -> 46187 | H28: 카카오뱅크 | I28: 3333-09-2683439 | J28: 최수연 | K28: 071110-4249620 | L28: 010-4652-5769 | M28: =IF(D28>0,EDATE(D28,36)-1,"") -> 47221 | N28: 수익금 확인
B29: 염영원 | C29: 10000000 | D29: 46126 | E29: 현금 | G29: =IF(D29>0,EDATE(D29,2),"") -> 46187 | H29: 우체국은행 | I29: 104678-02-090140 | J29: =IF(B29>0,B29,"") -> 염영원 | K29: 610118-1237216 | L29: 010-3895-0384 | M29: =IF(D29>0,EDATE(D29,36)-1,"") -> 47221
B30: 김지섭 | D30: 46123 | G30: =IF(D30>0,EDATE(D30,2),"") -> 46184 | H30: 국민은행 | I30: 543001-01-178604 | J30: 이보령 | K30: 840229-1730715 | L30: 010-4335-0369 | M30: =IF(D30>0,EDATE(D30,36)-1,"") -> 47218 | N30: 입금정보확인
B31: 김운호 | D31: 46123 | G31: =IF(D31>0,EDATE(D31,2),"") -> 46184 | H31: 국민은행 | I31: 543001-01-178604 | J31: 이보령 | K31: 591102-1548041 | L31: 010-6471-2886 | M31: =IF(D31>0,EDATE(D31,36)-1,"") -> 47218 | N31: 입금정보확인
B32: 서상진 | D32: 46123 | G32: =IF(D32>0,EDATE(D32,2),"") -> 46184 | H32: 국민은행 | I32: 543001-01-178604 | J32: 이보령 | K32: 550425-1547921 | L32: 010-8065-5448 | M32: =IF(D32>0,EDATE(D32,36)-1,"") -> 47218 | N32: 입금정보확인
B33: 김을태 | D33: 46123 | G33: =IF(D33>0,EDATE(D33,2),"") -> 46184 | H33: 국민은행 | I33: 543001-01-178604 | J33: 이보령 | K33: 560909-2001710 | L33: 010-8804-7179 | M33: =IF(D33>0,EDATE(D33,36)-1,"") -> 47218 | N33: 입금정보확인
B34: 김태희 | D34: 46123 | G34: =IF(D34>0,EDATE(D34,2),"") -> 46184 | H34: 국민은행 | I34: 543001-01-178604 | J34: 이보령 | K34: 921221-2408837 | L34: 010-5112-1416 | M34: =IF(D34>0,EDATE(D34,36)-1,"") -> 47218 | N34: 입금정보확인
B35: 김현자 | D35: 46123 | G35: =IF(D35>0,EDATE(D35,2),"") -> 46184 | H35: 국민은행 | I35: 543001-01-178604 | J35: 이보령 | K35: 600422-2543514 | L35: 010-6365-0889 | M35: =IF(D35>0,EDATE(D35,36)-1,"") -> 47218 | N35: 입금정보확인
B36: 임종숙 | D36: 46123 | G36: =IF(D36>0,EDATE(D36,2),"") -> 46184 | H36: 국민은행 | I36: 543001-01-178604 | J36: 이보령 | K36: 610722-2460019 | L36: 010-8322-2587 | M36: =IF(D36>0,EDATE(D36,36)-1,"") -> 47218 | N36: 입금정보확인
B37: 홍명희 | D37: 46123 | G37: =IF(D37>0,EDATE(D37,2),"") -> 46184 | H37: 국민은행 | I37: 543001-01-178604 | J37: 이보령 | K37: 520613-1908412 | L37: 010-3300-6897 | M37: =IF(D37>0,EDATE(D37,36)-1,"") -> 47218 | N37: 입금정보확인
B38: 송현미 | C38: 10000000 | D38: 46123 | E38: 현금 | F38: 800000 | G38: =IF(D38>0,EDATE(D38,2),"") -> 46184 | H38: 농협은행 | I38: 351-1331-464193 | J38: =IF(B38>0,B38,"") -> 송현미 | K38: 620108-2535213 | L38: 010-6689-1123 | M38: =IF(D38>0,EDATE(D38,36)-1,"") -> 47218
B39: 정윤숙 | C39: 10000000 | D39: 46123 | E39: 현금 | F39: 800000 | G39: =IF(D39>0,EDATE(D39,2),"") -> 46184 | H39: 새마을금고 | I39: 9003-3066-3314-0 | J39: =IF(B39>0,B39,"") -> 정윤숙 | K39: 670108-2812515 | L39: 010-8895-6899 | M39: =IF(D39>0,EDATE(D39,36)-1,"") -> 47218
B40: 신재교 | C40: 10000000 | D40: 46119 | E40: 현금 | F40: 500000 | G40: =IF(D40>0,EDATE(D40,2),"") -> 46180 | H40: 국민은행 | I40: 475825-88-135981 | J40: =IF(B40>0,B40,"") -> 신재교 | K40: 580525-2019323 | L40: 010-5038-2891 | M40: =IF(D40>0,EDATE(D40,36)-1,"") -> 47214 | N40: (내용확인-카톡)
...

Sheet 5월
A1: 2026년 5월 계약현황
A2: 추천인 | B2: 성명 | C2: 보증금(원) | D2: 입금일/결제일 | E2: 현금/카드 | F2: 수익금(원) | G2: 최초지급일 | H2: 계좌은행 | I2: 계좌번호 | J2: 예금주 | K2: 주민등록번호 | L2: 핸드폰번호 | M2: 계약만료일 | N2: 비고
G3: =IF(D3>0,EDATE(D3,2),"") | J3: =IF(B3>0,B3,"") | M3: =IF(D3>0,EDATE(D3,36)-1,"")
G4: =IF(D4>0,EDATE(D4,2),"") | J4: =IF(B4>0,B4,"") | M4: =IF(D4>0,EDATE(D4,36)-1,"")
G5: =IF(D5>0,EDATE(D5,2),"") | J5: =IF(B5>0,B5,"") | M5: =IF(D5>0,EDATE(D5,36)-1,"")
G6: =IF(D6>0,EDATE(D6,2),"") | J6: =IF(B6>0,B6,"") | M6: =IF(D6>0,EDATE(D6,36)-1,"")
G7: =IF(D7>0,EDATE(D7,2),"") | J7: =IF(B7>0,B7,"") | M7: =IF(D7>0,EDATE(D7,36)-1,"")
G8: =IF(D8>0,EDATE(D8,2),"") | J8: =IF(B8>0,B8,"") | M8: =IF(D8>0,EDATE(D8,36)-1,"")
G9: =IF(D9>0,EDATE(D9,2),"") | J9: =IF(B9>0,B9,"") | M9: =IF(D9>0,EDATE(D9,36)-1,"")
G10: =IF(D10>0,EDATE(D10,2),"") | J10: =IF(B10>0,B10,"") | M10: =IF(D10>0,EDATE(D10,36)-1,"")
G11: =IF(D11>0,EDATE(D11,2),"") | J11: =IF(B11>0,B11,"") | M11: =IF(D11>0,EDATE(D11,36)-1,"")
G12: =IF(D12>0,EDATE(D12,2),"") | J12: =IF(B12>0,B12,"") | M12: =IF(D12>0,EDATE(D12,36)-1,"")
G13: =IF(D13>0,EDATE(D13,2),"") | J13: =IF(B13>0,B13,"") | M13: =IF(D13>0,EDATE(D13,36)-1,"")
G14: =IF(D14>0,EDATE(D14,2),"") | J14: =IF(B14>0,B14,"") | M14: =IF(D14>0,EDATE(D14,36)-1,"")
... G300: =IF(D300>0,EDATE(D300,2),"") | J300: =IF(B300>0,B300,"") | M300: =IF(D300>0,EDATE(D300,36)-1,"")

Sheet 6월
A1: 2026년 6월 계약현황
A2: 추천인 | B2: 성명 | C2: 보증금(원) | D2: 입금일/결제일 | E2: 현금/카드 | F2: 수익금(원) | G2: 최초지급일 | H2: 계좌은행 | I2: 계좌번호 | J2: 예금주 | K2: 주민등록번호 | L2: 핸드폰번호 | M2: 계약만료일 | N2: 비고

Sheet 7월
A1: 2026년 7월 계약현황
A2: 추천인 | B2: 성명 | C2: 보증금(원) | D2: 입금일/결제일 | E2: 현금/카드 | F2: 수익금(원) | G2: 최초지급일 | H2: 계좌은행 | I2: 계좌번호 | J2: 예금주 | K2: 주민등록번호 | L2: 핸드폰번호 | M2: 계약만료일 | N2: 비고

Sheet 8월
A1: 2026년 8월 계약현황
A2: 추천인 | B2: 성명 | C2: 보증금(원) | D2: 입금일/결제일 | E2: 현금/카드 | F2: 수익금(원) | G2: 최초지급일 | H2: 계좌은행 | I2: 계좌번호 | J2: 예금주 | K2: 주민등록번호 | L2: 핸드폰번호 | M2: 계약만료일 | N2: 비고

Sheet 9월
A1: 2026년 9월 계약현황
A2: 추천인 | B2: 성명 | C2: 보증금(원) | D2: 입금일/결제일 | E2: 현금/카드 | F2: 수익금(원) | G2: 최초지급일 | H2: 계좌은행 | I2: 계좌번호 | J2: 예금주 | K2: 주민등록번호 | L2: 핸드폰번호 | M2: 계약만료일 | N2: 비고

Sheet 10월
A1: 2026년 10월 계약현황
A2: 추천인 | B2: 성명 | C2: 보증금(원) | D2: 입금일/결제일 | E2: 현금/카드 | F2: 수익금(원) | G2: 최초지급일 | H2: 계좌은행 | I2: 계좌번호 | J2: 예금주 | K2: 주민등록번호 | L2: 핸드폰번호 | M2: 계약만료일 | N2: 비고

Sheet 11월
A1: 2026년 11월 계약현황
A2: 추천인 | B2: 성명 | C2: 보증금(원) | D2: 입금일/결제일 | E2: 현금/카드 | F2: 수익금(원) | G2: 최초지급일 | H2: 계좌은행 | I2: 계좌번호 | J2: 예금주 | K2: 주민등록번호 | L2: 핸드폰번호 | M2: 계약만료일 | N2: 비고

Sheet 12월
A1: 2026년 12월 계약현황
A2: 추천인 | B2: 성명 | C2: 보증금(원) | D2: 입금일/결제일 | E2: 현금/카드 | F2: 수익금(원) | G2: 최초지급일 | H2: 계좌은행 | I2: 계좌번호 | J2: 예금주 | K2: 주민등록번호 | L2: 핸드폰번호 | M2: 계약만료일 | N2: 비고

Sheet 모니터링계약
A1: 2026년 모니터링 계약 현황
A2: No. | B2: 성명 | C2: 보증금(원) | D2: 입금일/결제일 | E2: 현금/카드 | F2: 수익금(원) | G2: 최초지급일 | H2: 계좌은행 | I2: 계좌번호 | J2: 예금주 | K2: 주민등록번호 | L2: 핸드폰번호 | M2: 계약만료일 | N2: 비고
A3: 1 | B3: 이선영 | C3: 3300000 | D3: 2026.1.28 | E3: 현금 | F3: 300000 | G3: 2026.2.28 | H3: 우체국 | I3: 400457-02-176981 | J3: 이선영 | K3: 790729-2192612 | L3: 010-8831-6873 | M3: 2026.2.27
A4: 2 | B4: 김미향 | G4: 2026.4.3 | H4: 토스 | I4: 1001-4422-5918 | J4: 김미향 | K4: 840826-2056411 | L4: 010-2514-1826

Sheet 검색
A1: 계약자 정보 검색 및 원본 이동
A3: 사용방법: C4에 이름을 입력하면 1월~12월 및 모니터링계약 전체에서 검색됩니다. 목록의 '이동'을 클릭하면 원본 월별 시트의 해당 성명 셀로 이동합니다. | O3: 검색대상 | P3: 포함 | Q3: 계약월 | R3: 성명 | S3: 보증금 | T3: 입금일/결제일 | U3: 현금/카드 | V3: 수익금 | W3: 최초지급일 | X3: 계좌은행 | Y3: 계좌번호 | Z3: 예금주 | AA3: 주민등록번호 | AB3: 핸드폰번호 | AC3: 비고
B4: 검색 이름 | C4: 하주현 | O4: 1월 | P4: Y | Q4: =IF(TRIM($C$4)="","",IF($O$4<>"","1월",IF($O$5<>"","2월",IF($O$6<>"","3월",IF($O$7<>"","4월",IF($O$8<>"","모니터링계약","")))))) -> 1월 | R4: =IF($Q$4="","",IF($Q$4="1월",INDEX('1월'!B:B,$O$4),IF($Q$4="2월",INDEX('2월'!B:B,$O$5),IF($Q$4="3월",INDEX('3월'!B:B,$O$6),IF($Q$4="4월",INDEX('4월'!B:B,$O$7),IF($Q$4="모니터링계약",INDEX(모니터링계약!B:B,$O$8),"")))))) -> #VALUE! | S4: =IF($Q$4="","",IF($Q$4="1월",INDEX('1월'!C:C,$O$4),IF($Q$4="2월",INDEX('2월'!C:C,$O$5),IF($Q$4="3월",INDEX('3월'!C:C,$O$6),IF($Q$4="4월",INDEX('4월'!C:C,$O$7),IF($Q$4="모니터링계약",INDEX(모니터링계약!C:C,$O$8),"")))))) -> #VALUE! | T4: =IF($Q$4="","",IF($Q$4="1월",INDEX('1월'!D:D,$O$4),IF($Q$4="2월",INDEX('2월'!D:D,$O$5),IF($Q$4="3월",INDEX('3월'!D:D,$O$6),IF($Q$4="4월",INDEX('4월'!D:D,$O$7),IF($Q$4="모니터링계약",INDEX(모니터링계약!D:D,$O$8),"")))))) -> #VALUE! | U4: =IF($Q$4="","",IF($Q$4="1월",INDEX('1월'!E:E,$O$4),IF($Q$4="2월",INDEX('2월'!E:E,$O$5),IF($Q$4="3월",INDEX('3월'!E:E,$O$6),IF($Q$4="4월",INDEX('4월'!E:E,$O$7),IF($Q$4="모니터링계약",INDEX(모니터링계약!E:E,$O$8),"")))))) -> #VALUE! | V4: =IF($Q$4="","",IF($Q$4="1월",INDEX('1월'!F:F,$O$4),IF($Q$4="2월",INDEX('2월'!F:F,$O$5),IF($Q$4="3월",INDEX('3월'!F:F,$O$6),IF($Q$4="4월",INDEX('4월'!F:F,$O$7),IF($Q$4="모니터링계약",INDEX(모니터링계약!F:F,$O$8),"")))))) -> #VALUE! | W4: =IF($Q$4="","",IF($Q$4="1월",INDEX('1월'!G:G,$O$4),IF($Q$4="2월",INDEX('2월'!G:G,$O$5),IF($Q$4="3월",INDEX('3월'!G:G,$O$6),IF($Q$4="4월",INDEX('4월'!G:G,$O$7),IF($Q$4="모니터링계약",INDEX(모니터링계약!G:G,$O$8),"")))))) -> #VALUE! | X4: =IF($Q$4="","",IF($Q$4="1월",INDEX('1월'!H:H,$O$4),IF($Q$4="2월",INDEX('2월'!H:H,$O$5),IF($Q$4="3월",INDEX('3월'!H:H,$O$6),IF($Q$4="4월",INDEX('4월'!H:H,$O$7),IF($Q$4="모니터링계약",INDEX(모니터링계약!H:H,$O$8),"")))))) -> #VALUE! | Y4: =IF($Q$4="","",IF($Q$4="1월",INDEX('1월'!I:I,$O$4),IF($Q$4="2월",INDEX('2월'!I:I,$O$5),IF($Q$4="3월",INDEX('3월'!I:I,$O$6),IF($Q$4="4월",INDEX('4월'!I:I,$O$7),IF($Q$4="모니터링계약",INDEX(모니터링계약!I:I,$O$8),"")))))) -> #VALUE! | Z4: =IF($Q$4="","",IF($Q$4="1월",INDEX('1월'!J:J,$O$4),IF($Q$4="2월",INDEX('2월'!J:J,$O$5),IF($Q$4="3월",INDEX('3월'!J:J,$O$6),IF($Q$4="4월",INDEX('4월'!J:J,$O$7),IF($Q$4="모니터링계약",INDEX(모니터링계약!J:J,$O$8),"")))))) -> #VALUE! | AA4: =IF($Q$4="","",IF($Q$4="1월",INDEX('1월'!K:K,$O$4),IF($Q$4="2월",INDEX('2월'!K:K,$O$5),IF($Q$4="3월",INDEX('3월'!K:K,$O$6),IF($Q$4="4월",INDEX('4월'!K:K,$O$7),IF($Q$4="모니터링계약",INDEX(모니터링계약!K:K,$O$8),"")))))) -> #VALUE! | AB4: =IF($Q$4="","",IF($Q$4="1월",INDEX('1월'!L:L,$O$4),IF($Q$4="2월",INDEX('2월'!L:L,$O$5),IF($Q$4="3월",INDEX('3월'!L:L,$O$6),IF($Q$4="4월",INDEX('4월'!L:L,$O$7),IF($Q$4="모니터링계약",INDEX(모니터링계약!L:L,$O$8),"")))))) -> #VALUE! | AC4: =IF(TRIM($C$4)="","",SUM($P$4:$P$8)) -> 0
B5: 주민등록번호 표시여부 | C5: 표시 | D5: ※ 숨기려면 C5를 미표시로 변경 | O5: 2월 | P5: Y
B6: 검색 건수 | C6: =COUNT(SEARCH_DB!$P:$P) -> 1 | O6: 3월 | P6: Y
O7: 4월 | P7: Y
B8: 복사용 결과 | O8: 5월 | P8: Y
C9: =IF($C$4="","검색 이름을 입력하세요.",IF($C$6=0,"검색 결과가 없습니다.",CONCATENATE("[계약정보]",CHAR(10),"계약월: ",$B$24,CHAR(10),"성명: ",$D$24,CHAR(10),"보증금: ",IF($E$24="","",TEXT($E$24,"#,##0원")),CHAR(10),"입금일/결제일: ",IF($F$24="","",IFERROR(TEXT($F$24,"yyyy-mm-dd"),$F$24)),CHAR(10),"현금/카드: ",$G$24,CHAR(10),"수익금: ",IF($H$24="","",TEXT($H$24,"#,##0원")),CHAR(10),"최초지급일: ",IF($I$24="","",IFERROR(TEXT($I$24,"yyyy-mm-dd"),$I$24)),CHAR(10),CHAR(10),"[계좌정보]",CHAR(10),"계좌은행: ",$J$24,CHAR(10),"계좌번호: ",$K$24,CHAR(10),"예금주: ",$L$24,CHAR(10),IF($C$5="표시",CONCATENATE("주민등록번호: ",$M$24,CHAR(10)),""),CHAR(10),"[연락처]",CHAR(10),"핸드폰번호: ",$N$24))) -> [계약정보] 계약월: 2월 성명: 하주현 보증금: 50,000,000원 입금일/결제일: 2026.2.10 현금/카드: 현금 수익금: 0원 최초지급일: 2026.4.10 [계좌정보] 계좌은행: 국민 계좌번호: 740901-01-293331 예금주: 하주현 주민등록번호: 701208-2055626 [연락처] 핸드폰번호: 010-7530-5544 | O9: 6월 | P9: Y
O10: 7월 | P10: Y
O11: 8월 | P11: Y
O12: 9월 | P12: Y
O13: 10월 | P13: Y
O14: 11월 | P14: Y
O15: 12월 | P15: Y
O16: 모니터링계약 | P16: Y
A23: 이동 | B23: 계약월 | C23: 원본행 | D23: 성명 | E23: 보증금 | F23: 입금일/결제일 | G23: 현금/카드 | H23: 수익금 | I23: 최초지급일 | J23: 계좌은행 | K23: 계좌번호 | L23: 예금주 | M23: 주민등록번호 | N23: 핸드폰번호
A24: =IF($B24="","",HYPERLINK("#'"&$B24&"'!B"&$C24,"이동")) -> 이동 | B24: =IFERROR(INDEX(SEARCH_DB!$B:$B,MATCH(ROW(A1),SEARCH_DB!$P:$P,0)),"") -> 2월 | C24: =IFERROR(INDEX(SEARCH_DB!$C:$C,MATCH(ROW(A1),SEARCH_DB!$P:$P,0)),"") -> 25 | D24: =IFERROR(INDEX(SEARCH_DB!$E:$E,MATCH(ROW(A1),SEARCH_DB!$P:$P,0)),"") -> 하주현 | E24: =IFERROR(INDEX(SEARCH_DB!$F:$F,MATCH(ROW(A1),SEARCH_DB!$P:$P,0)),"") -> 50000000 | F24: =IFERROR(INDEX(SEARCH_DB!$G:$G,MATCH(ROW(A1),SEARCH_DB!$P:$P,0)),"") -> 2026.2.10 | G24: =IFERROR(INDEX(SEARCH_DB!$H:$H,MATCH(ROW(A1),SEARCH_DB!$P:$P,0)),"") -> 현금 | H24: =IFERROR(INDEX(SEARCH_DB!$I:$I,MATCH(ROW(A1),SEARCH_DB!$P:$P,0)),"") -> 0 | I24: =IFERROR(INDEX(SEARCH_DB!$J:$J,MATCH(ROW(A1),SEARCH_DB!$P:$P,0)),"") -> 2026.4.10 | J24: =IFERROR(INDEX(SEARCH_DB!$K:$K,MATCH(ROW(A1),SEARCH_DB!$P:$P,0)),"") -> 국민 | K24: =IFERROR(INDEX(SEARCH_DB!$L:$L,MATCH(ROW(A1),SEARCH_DB!$P:$P,0)),"") -> 740901-01-293331 | L24: =IFERROR(INDEX(SEARCH_DB!$M:$M,MATCH(ROW(A1),SEARCH_DB!$P:$P,0)),"") -> 하주현 | M24: =IF($C$5="표시",IFERROR(INDEX(SEARCH_DB!$N:$N,MATCH(ROW(A1),SEARCH_DB!$P:$P,0)),""),"") -> 701208-2055626 | N24: =IFERROR(INDEX(SEARCH_DB!$O:$O,MATCH(ROW(A1),SEARCH_DB!$P:$P,0)),"") -> 010-7530-5544
A25: =IF($B25="","",HYPERLINK("#'"&$B25&"'!B"&$C25,"이동")) | B25: =IFERROR(INDEX(SEARCH_DB!$B:$B,MATCH(ROW(A2),SEARCH_DB!$P:$P,0)),"") | C25: =IFERROR(INDEX(SEARCH_DB!$C:$C,MATCH(ROW(A2),SEARCH_DB!$P:$P,0)),"") | D25: =IFERROR(INDEX(SEARCH_DB!$E:$E,MATCH(ROW(A2),SEARCH_DB!$P:$P,0)),"") | E25: =IFERROR(INDEX(SEARCH_DB!$F:$F,MATCH(ROW(A2),SEARCH_DB!$P:$P,0)),"") | F25: =IFERROR(INDEX(SEARCH_DB!$G:$G,MATCH(ROW(A2),SEARCH_DB!$P:$P,0)),"") | G25: =IFERROR(INDEX(SEARCH_DB!$H:$H,MATCH(ROW(A2),SEARCH_DB!$P:$P,0)),"") | H25: =IFERROR(INDEX(SEARCH_DB!$I:$I,MATCH(ROW(A2),SEARCH_DB!$P:$P,0)),"") | I25: =IFERROR(INDEX(SEARCH_DB!$J:$J,MATCH(ROW(A2),SEARCH_DB!$P:$P,0)),"") | J25: =IFERROR(INDEX(SEARCH_DB!$K:$K,MATCH(ROW(A2),SEARCH_DB!$P:$P,0)),"") | K25: =IFERROR(INDEX(SEARCH_DB!$L:$L,MATCH(ROW(A2),SEARCH_DB!$P:$P,0)),"") | L25: =IFERROR(INDEX(SEARCH_DB!$M:$M,MATCH(ROW(A2),SEARCH_DB!$P:$P,0)),"") | M25: =IF($C$5="표시",IFERROR(INDEX(SEARCH_DB!$N:$N,MATCH(ROW(A2),SEARCH_DB!$P:$P,0)),""),"") | N25: =IFERROR(INDEX(SEARCH_DB!$O:$O,MATCH(ROW(A2),SEARCH_DB!$P:$P,0)),"")
A26: =IF($B26="","",HYPERLINK("#'"&$B26&"'!B"&$C26,"이동")) | B26: =IFERROR(INDEX(SEARCH_DB!$B:$B,MATCH(ROW(A3),SEARCH_DB!$P:$P,0)),"") | C26: =IFERROR(INDEX(SEARCH_DB!$C:$C,MATCH(ROW(A3),SEARCH_DB!$P:$P,0)),"") | D26: =IFERROR(INDEX(SEARCH_DB!$E:$E,MATCH(ROW(A3),SEARCH_DB!$P:$P,0)),"") | E26: =IFERROR(INDEX(SEARCH_DB!$F:$F,MATCH(ROW(A3),SEARCH_DB!$P:$P,0)),"") | F26: =IFERROR(INDEX(SEARCH_DB!$G:$G,MATCH(ROW(A3),SEARCH_DB!$P:$P,0)),"") | G26: =IFERROR(INDEX(SEARCH_DB!$H:$H,MATCH(ROW(A3),SEARCH_DB!$P:$P,0)),"") | H26: =IFERROR(INDEX(SEARCH_DB!$I:$I,MATCH(ROW(A3),SEARCH_DB!$P:$P,0)),"") | I26: =IFERROR(INDEX(SEARCH_DB!$J:$J,MATCH(ROW(A3),SEARCH_DB!$P:$P,0)),"") | J26: =IFERROR(INDEX(SEARCH_DB!$K:$K,MATCH(ROW(A3),SEARCH_DB!$P:$P,0)),"") | K26: =IFERROR(INDEX(SEARCH_DB!$L:$L,MATCH(ROW(A3),SEARCH_DB!$P:$P,0)),"") | L26: =IFERROR(INDEX(SEARCH_DB!$M:$M,MATCH(ROW(A3),SEARCH_DB!$P:$P,0)),"") | M26: =IF($C$5="표시",IFERROR(INDEX(SEARCH_DB!$N:$N,MATCH(ROW(A3),SEARCH_DB!$P:$P,0)),""),"") | N26: =IFERROR(INDEX(SEARCH_DB!$O:$O,MATCH(ROW(A3),SEARCH_DB!$P:$P,0)),"")
A27: =IF($B27="","",HYPERLINK("#'"&$B27&"'!B"&$C27,"이동")) | B27: =IFERROR(INDEX(SEARCH_DB!$B:$B,MATCH(ROW(A4),SEARCH_DB!$P:$P,0)),"") | C27: =IFERROR(INDEX(SEARCH_DB!$C:$C,MATCH(ROW(A4),SEARCH_DB!$P:$P,0)),"") | D27: =IFERROR(INDEX(SEARCH_DB!$E:$E,MATCH(ROW(A4),SEARCH_DB!$P:$P,0)),"") | E27: =IFERROR(INDEX(SEARCH_DB!$F:$F,MATCH(ROW(A4),SEARCH_DB!$P:$P,0)),"") | F27: =IFERROR(INDEX(SEARCH_DB!$G:$G,MATCH(ROW(A4),SEARCH_DB!$P:$P,0)),"") | G27: =IFERROR(INDEX(SEARCH_DB!$H:$H,MATCH(ROW(A4),SEARCH_DB!$P:$P,0)),"") | H27: =IFERROR(INDEX(SEARCH_DB!$I:$I,MATCH(ROW(A4),SEARCH_DB!$P:$P,0)),"") | I27: =IFERROR(INDEX(SEARCH_DB!$J:$J,MATCH(ROW(A4),SEARCH_DB!$P:$P,0)),"") | J27: =IFERROR(INDEX(SEARCH_DB!$K:$K,MATCH(ROW(A4),SEARCH_DB!$P:$P,0)),"") | K27: =IFERROR(INDEX(SEARCH_DB!$L:$L,MATCH(ROW(A4),SEARCH_DB!$P:$P,0)),"") | L27: =IFERROR(INDEX(SEARCH_DB!$M:$M,MATCH(ROW(A4),SEARCH_DB!$P:$P,0)),"") | M27: =IF($C$5="표시",IFERROR(INDEX(SEARCH_DB!$N:$N,MATCH(ROW(A4),SEARCH_DB!$P:$P,0)),""),"") | N27: =IFERROR(INDEX(SEARCH_DB!$O:$O,MATCH(ROW(A4),SEARCH_DB!$P:$P,0)),"")
A28: =IF($B28="","",HYPERLINK("#'"&$B28&"'!B"&$C28,"이동")) | B28: =IFERROR(INDEX(SEARCH_DB!$B:$B,MATCH(ROW(A5),SEARCH_DB!$P:$P,0)),"") | C28: =IFERROR(INDEX(SEARCH_DB!$C:$C,MATCH(ROW(A5),SEARCH_DB!$P:$P,0)),"") | D28: =IFERROR(INDEX(SEARCH_DB!$E:$E,MATCH(ROW(A5),SEARCH_DB!$P:$P,0)),"") | E28: =IFERROR(INDEX(SEARCH_DB!$F:$F,MATCH(ROW(A5),SEARCH_DB!$P:$P,0)),"") | F28: =IFERROR(INDEX(SEARCH_DB!$G:$G,MATCH(ROW(A5),SEARCH_DB!$P:$P,0)),"") | G28: =IFERROR(INDEX(SEARCH_DB!$H:$H,MATCH(ROW(A5),SEARCH_DB!$P:$P,0)),"") | H28: =IFERROR(INDEX(SEARCH_DB!$I:$I,MATCH(ROW(A5),SEARCH_DB!$P:$P,0)),"") | I28: =IFERROR(INDEX(SEARCH_DB!$J:$J,MATCH(ROW(A5),SEARCH_DB!$P:$P,0)),"") | J28: =IFERROR(INDEX(SEARCH_DB!$K:$K,MATCH(ROW(A5),SEARCH_DB!$P:$P,0)),"") | K28: =IFERROR(INDEX(SEARCH_DB!$L:$L,MATCH(ROW(A5),SEARCH_DB!$P:$P,0)),"") | L28: =IFERROR(INDEX(SEARCH_DB!$M:$M,MATCH(ROW(A5),SEARCH_DB!$P:$P,0)),"") | M28: =IF($C$5="표시",IFERROR(INDEX(SEARCH_DB!$N:$N,MATCH(ROW(A5),SEARCH_DB!$P:$P,0)),""),"") | N28: =IFERROR(INDEX(SEARCH_DB!$O:$O,MATCH(ROW(A5),SEARCH_DB!$P:$P,0)),"")
A29: =IF($B29="","",HYPERLINK("#'"&$B29&"'!B"&$C29,"이동")) | B29: =IFERROR(INDEX(SEARCH_DB!$B:$B,MATCH(ROW(A6),SEARCH_DB!$P:$P,0)),"") | C29: =IFERROR(INDEX(SEARCH_DB!$C:$C,MATCH(ROW(A6),SEARCH_DB!$P:$P,0)),"") | D29: =IFERROR(INDEX(SEARCH_DB!$E:$E,MATCH(ROW(A6),SEARCH_DB!$P:$P,0)),"") | E29: =IFERROR(INDEX(SEARCH_DB!$F:$F,MATCH(ROW(A6),SEARCH_DB!$P:$P,0)),"") | F29: =IFERROR(INDEX(SEARCH_DB!$G:$G,MATCH(ROW(A6),SEARCH_DB!$P:$P,0)),"") | G29: =IFERROR(INDEX(SEARCH_DB!$H:$H,MATCH(ROW(A6),SEARCH_DB!$P:$P,0)),"") | H29: =IFERROR(INDEX(SEARCH_DB!$I:$I,MATCH(ROW(A6),SEARCH_DB!$P:$P,0)),"") | I29: =IFERROR(INDEX(SEARCH_DB!$J:$J,MATCH(ROW(A6),SEARCH_DB!$P:$P,0)),"") | J29: =IFERROR(INDEX(SEARCH_DB!$K:$K,MATCH(ROW(A6),SEARCH_DB!$P:$P,0)),"") | K29: =IFERROR(INDEX(SEARCH_DB!$L:$L,MATCH(ROW(A6),SEARCH_DB!$P:$P,0)),"") | L29: =IFERROR(INDEX(SEARCH_DB!$M:$M,MATCH(ROW(A6),SEARCH_DB!$P:$P,0)),"") | M29: =IF($C$5="표시",IFERROR(INDEX(SEARCH_DB!$N:$N,MATCH(ROW(A6),SEARCH_DB!$P:$P,0)),""),"") | N29: =IFERROR(INDEX(SEARCH_DB!$O:$O,MATCH(ROW(A6),SEARCH_DB!$P:$P,0)),"")
A30: =IF($B30="","",HYPERLINK("#'"&$B30&"'!B"&$C30,"이동")) | B30: =IFERROR(INDEX(SEARCH_DB!$B:$B,MATCH(ROW(A7),SEARCH_DB!$P:$P,0)),"") | C30: =IFERROR(INDEX(SEARCH_DB!$C:$C,MATCH(ROW(A7),SEARCH_DB!$P:$P,0)),"") | D30: =IFERROR(INDEX(SEARCH_DB!$E:$E,MATCH(ROW(A7),SEARCH_DB!$P:$P,0)),"") | E30: =IFERROR(INDEX(SEARCH_DB!$F:$F,MATCH(ROW(A7),SEARCH_DB!$P:$P,0)),"") | F30: =IFERROR(INDEX(SEARCH_DB!$G:$G,MATCH(ROW(A7),SEARCH_DB!$P:$P,0)),"") | G30: =IFERROR(INDEX(SEARCH_DB!$H:$H,MATCH(ROW(A7),SEARCH_DB!$P:$P,0)),"") | H30: =IFERROR(INDEX(SEARCH_DB!$I:$I,MATCH(ROW(A7),SEARCH_DB!$P:$P,0)),"") | I30: =IFERROR(INDEX(SEARCH_DB!$J:$J,MATCH(ROW(A7),SEARCH_DB!$P:$P,0)),"") | J30: =IFERROR(INDEX(SEARCH_DB!$K:$K,MATCH(ROW(A7),SEARCH_DB!$P:$P,0)),"") | K30: =IFERROR(INDEX(SEARCH_DB!$L:$L,MATCH(ROW(A7),SEARCH_DB!$P:$P,0)),"") | L30: =IFERROR(INDEX(SEARCH_DB!$M:$M,MATCH(ROW(A7),SEARCH_DB!$P:$P,0)),"") | M30: =IF($C$5="표시",IFERROR(INDEX(SEARCH_DB!$N:$N,MATCH(ROW(A7),SEARCH_DB!$P:$P,0)),""),"") | N30: =IFERROR(INDEX(SEARCH_DB!$O:$O,MATCH(ROW(A7),SEARCH_DB!$P:$P,0)),"")
A31: =IF($B31="","",HYPERLINK("#'"&$B31&"'!B"&$C31,"이동")) | B31: =IFERROR(INDEX(SEARCH_DB!$B:$B,MATCH(ROW(A8),SEARCH_DB!$P:$P,0)),"") | C31: =IFERROR(INDEX(SEARCH_DB!$C:$C,MATCH(ROW(A8),SEARCH_DB!$P:$P,0)),"") | D31: =IFERROR(INDEX(SEARCH_DB!$E:$E,MATCH(ROW(A8),SEARCH_DB!$P:$P,0)),"") | E31: =IFERROR(INDEX(SEARCH_DB!$F:$F,MATCH(ROW(A8),SEARCH_DB!$P:$P,0)),"") | F31: =IFERROR(INDEX(SEARCH_DB!$G:$G,MATCH(ROW(A8),SEARCH_DB!$P:$P,0)),"") | G31: =IFERROR(INDEX(SEARCH_DB!$H:$H,MATCH(ROW(A8),SEARCH_DB!$P:$P,0)),"") | H31: =IFERROR(INDEX(SEARCH_DB!$I:$I,MATCH(ROW(A8),SEARCH_DB!$P:$P,0)),"") | I31: =IFERROR(INDEX(SEARCH_DB!$J:$J,MATCH(ROW(A8),SEARCH_DB!$P:$P,0)),"") | J31: =IFERROR(INDEX(SEARCH_DB!$K:$K,MATCH(ROW(A8),SEARCH_DB!$P:$P,0)),"") | K31: =IFERROR(INDEX(SEARCH_DB!$L:$L,MATCH(ROW(A8),SEARCH_DB!$P:$P,0)),"") | L31: =IFERROR(INDEX(SEARCH_DB!$M:$M,MATCH(ROW(A8),SEARCH_DB!$P:$P,0)),"") | M31: =IF($C$5="표시",IFERROR(INDEX(SEARCH_DB!$N:$N,MATCH(ROW(A8),SEARCH_DB!$P:$P,0)),""),"") | N31: =IFERROR(INDEX(SEARCH_DB!$O:$O,MATCH(ROW(A8),SEARCH_DB!$P:$P,0)),"")
A32: =IF($B32="","",HYPERLINK("#'"&$B32&"'!B"&$C32,"이동")) | B32: =IFERROR(INDEX(SEARCH_DB!$B:$B,MATCH(ROW(A9),SEARCH_DB!$P:$P,0)),"") | C32: =IFERROR(INDEX(SEARCH_DB!$C:$C,MATCH(ROW(A9),SEARCH_DB!$P:$P,0)),"") | D32: =IFERROR(INDEX(SEARCH_DB!$E:$E,MATCH(ROW(A9),SEARCH_DB!$P:$P,0)),"") | E32: =IFERROR(INDEX(SEARCH_DB!$F:$F,MATCH(ROW(A9),SEARCH_DB!$P:$P,0)),"") | F32: =IFERROR(INDEX(SEARCH_DB!$G:$G,MATCH(ROW(A9),SEARCH_DB!$P:$P,0)),"") | G32: =IFERROR(INDEX(SEARCH_DB!$H:$H,MATCH(ROW(A9),SEARCH_DB!$P:$P,0)),"") | H32: =IFERROR(INDEX(SEARCH_DB!$I:$I,MATCH(ROW(A9),SEARCH_DB!$P:$P,0)),"") | I32: =IFERROR(INDEX(SEARCH_DB!$J:$J,MATCH(ROW(A9),SEARCH_DB!$P:$P,0)),"") | J32: =IFERROR(INDEX(SEARCH_DB!$K:$K,MATCH(ROW(A9),SEARCH_DB!$P:$P,0)),"") | K32: =IFERROR(INDEX(SEARCH_DB!$L:$L,MATCH(ROW(A9),SEARCH_DB!$P:$P,0)),"") | L32: =IFERROR(INDEX(SEARCH_DB!$M:$M,MATCH(ROW(A9),SEARCH_DB!$P:$P,0)),"") | M32: =IF($C$5="표시",IFERROR(INDEX(SEARCH_DB!$N:$N,MATCH(ROW(A9),SEARCH_DB!$P:$P,0)),""),"") | N32: =IFERROR(INDEX(SEARCH_DB!$O:$O,MATCH(ROW(A9),SEARCH_DB!$P:$P,0)),"")
A33: =IF($B33="","",HYPERLINK("#'"&$B33&"'!B"&$C33,"이동")) | B33: =IFERROR(INDEX(SEARCH_DB!$B:$B,MATCH(ROW(A10),SEARCH_DB!$P:$P,0)),"") | C33: =IFERROR(INDEX(SEARCH_DB!$C:$C,MATCH(ROW(A10),SEARCH_DB!$P:$P,0)),"") | D33: =IFERROR(INDEX(SEARCH_DB!$E:$E,MATCH(ROW(A10),SEARCH_DB!$P:$P,0)),"") | E33: =IFERROR(INDEX(SEARCH_DB!$F:$F,MATCH(ROW(A10),SEARCH_DB!$P:$P,0)),"") | F33: =IFERROR(INDEX(SEARCH_DB!$G:$G,MATCH(ROW(A10),SEARCH_DB!$P:$P,0)),"") | G33: =IFERROR(INDEX(SEARCH_DB!$H:$H,MATCH(ROW(A10),SEARCH_DB!$P:$P,0)),"") | H33: =IFERROR(INDEX(SEARCH_DB!$I:$I,MATCH(ROW(A10),SEARCH_DB!$P:$P,0)),"") | I33: =IFERROR(INDEX(SEARCH_DB!$J:$J,MATCH(ROW(A10),SEARCH_DB!$P:$P,0)),"") | J33: =IFERROR(INDEX(SEARCH_DB!$K:$K,MATCH(ROW(A10),SEARCH_DB!$P:$P,0)),"") | K33: =IFERROR(INDEX(SEARCH_DB!$L:$L,MATCH(ROW(A10),SEARCH_DB!$P:$P,0)),"") | L33: =IFERROR(INDEX(SEARCH_DB!$M:$M,MATCH(ROW(A10),SEARCH_DB!$P:$P,0)),"") | M33: =IF($C$5="표시",IFERROR(INDEX(SEARCH_DB!$N:$N,MATCH(ROW(A10),SEARCH_DB!$P:$P,0)),""),"") | N33: =IFERROR(INDEX(SEARCH_DB!$O:$O,MATCH(ROW(A10),SEARCH_DB!$P:$P,0)),"")
A34: =IF($B34="","",HYPERLINK("#'"&$B34&"'!B"&$C34,"이동")) | B34: =IFERROR(INDEX(SEARCH_DB!$B:$B,MATCH(ROW(A11),SEARCH_DB!$P:$P,0)),"") | C34: =IFERROR(INDEX(SEARCH_DB!$C:$C,MATCH(ROW(A11),SEARCH_DB!$P:$P,0)),"") | D34: =IFERROR(INDEX(SEARCH_DB!$E:$E,MATCH(ROW(A11),SEARCH_DB!$P:$P,0)),"") | E34: =IFERROR(INDEX(SEARCH_DB!$F:$F,MATCH(ROW(A11),SEARCH_DB!$P:$P,0)),"") | F34: =IFERROR(INDEX(SEARCH_DB!$G:$G,MATCH(ROW(A11),SEARCH_DB!$P:$P,0)),"") | G34: =IFERROR(INDEX(SEARCH_DB!$H:$H,MATCH(ROW(A11),SEARCH_DB!$P:$P,0)),"") | H34: =IFERROR(INDEX(SEARCH_DB!$I:$I,MATCH(ROW(A11),SEARCH_DB!$P:$P,0)),"") | I34: =IFERROR(INDEX(SEARCH_DB!$J:$J,MATCH(ROW(A11),SEARCH_DB!$P:$P,0)),"") | J34: =IFERROR(INDEX(SEARCH_DB!$K:$K,MATCH(ROW(A11),SEARCH_DB!$P:$P,0)),"") | K34: =IFERROR(INDEX(SEARCH_DB!$L:$L,MATCH(ROW(A11),SEARCH_DB!$P:$P,0)),"") | L34: =IFERROR(INDEX(SEARCH_DB!$M:$M,MATCH(ROW(A11),SEARCH_DB!$P:$P,0)),"") | M34: =IF($C$5="표시",IFERROR(INDEX(SEARCH_DB!$N:$N,MATCH(ROW(A11),SEARCH_DB!$P:$P,0)),""),"") | N34: =IFERROR(INDEX(SEARCH_DB!$O:$O,MATCH(ROW(A11),SEARCH_DB!$P:$P,0)),"")
A35: =IF($B35="","",HYPERLINK("#'"&$B35&"'!B"&$C35,"이동")) | B35: =IFERROR(INDEX(SEARCH_DB!$B:$B,MATCH(ROW(A12),SEARCH_DB!$P:$P,0)),"") | C35: =IFERROR(INDEX(SEARCH_DB!$C:$C,MATCH(ROW(A12),SEARCH_DB!$P:$P,0)),"") | D35: =IFERROR(INDEX(SEARCH_DB!$E:$E,MATCH(ROW(A12),SEARCH_DB!$P:$P,0)),"") | E35: =IFERROR(INDEX(SEARCH_DB!$F:$F,MATCH(ROW(A12),SEARCH_DB!$P:$P,0)),"") | F35: =IFERROR(INDEX(SEARCH_DB!$G:$G,MATCH(ROW(A12),SEARCH_DB!$P:$P,0)),"") | G35: =IFERROR(INDEX(SEARCH_DB!$H:$H,MATCH(ROW(A12),SEARCH_DB!$P:$P,0)),"") | H35: =IFERROR(INDEX(SEARCH_DB!$I:$I,MATCH(ROW(A12),SEARCH_DB!$P:$P,0)),"") | I35: =IFERROR(INDEX(SEARCH_DB!$J:$J,MATCH(ROW(A12),SEARCH_DB!$P:$P,0)),"") | J35: =IFERROR(INDEX(SEARCH_DB!$K:$K,MATCH(ROW(A12),SEARCH_DB!$P:$P,0)),"") | K35: =IFERROR(INDEX(SEARCH_DB!$L:$L,MATCH(ROW(A12),SEARCH_DB!$P:$P,0)),"") | L35: =IFERROR(INDEX(SEARCH_DB!$M:$M,MATCH(ROW(A12),SEARCH_DB!$P:$P,0)),"") | M35: =IF($C$5="표시",IFERROR(INDEX(SEARCH_DB!$N:$N,MATCH(ROW(A12),SEARCH_DB!$P:$P,0)),""),"") | N35: =IFERROR(INDEX(SEARCH_DB!$O:$O,MATCH(ROW(A12),SEARCH_DB!$P:$P,0)),"")
... A300: =IF($B300="","",HYPERLINK("#'"&$B300&"'!B"&$C300,"이동")) | B300: =IFERROR(INDEX(SEARCH_DB!$B:$B,MATCH(ROW(A277),SEARCH_DB!$P:$P,0)),"") | C300: =IFERROR(INDEX(SEARCH_DB!$C:$C,MATCH(ROW(A277),SEARCH_DB!$P:$P,0)),"") | D300: =IFERROR(INDEX(SEARCH_DB!$E:$E,MATCH(ROW(A277),SEARCH_DB!$P:$P,0)),"") | E300: =IFERROR(INDEX(SEARCH_DB!$F:$F,MATCH(ROW(A277),SEARCH_DB!$P:$P,0)),"") | F300: =IFERROR(INDEX(SEARCH_DB!$G:$G,MATCH(ROW(A277),SEARCH_DB!$P:$P,0)),"") | G300: =IFERROR(INDEX(SEARCH_DB!$H:$H,MATCH(ROW(A277),SEARCH_DB!$P:$P,0)),"") | H300: =IFERROR(INDEX(SEARCH_DB!$I:$I,MATCH(ROW(A277),SEARCH_DB!$P:$P,0)),"") | I300: =IFERROR(INDEX(SEARCH_DB!$J:$J,MATCH(ROW(A277),SEARCH_DB!$P:$P,0)),"") | J300: =IFERROR(INDEX(SEARCH_DB!$K:$K,MATCH(ROW(A277),SEARCH_DB!$P:$P,0)),"") | K300: =IFERROR(INDEX(SEARCH_DB!$L:$L,MATCH(ROW(A277),SEARCH_DB!$P:$P,0)),"") | L300: =IFERROR(INDEX(SEARCH_DB!$M:$M,MATCH(ROW(A277),SEARCH_DB!$P:$P,0)),"") | M300: =IF($C$5="표시",IFERROR(INDEX(SEARCH_DB!$N:$N,MATCH(ROW(A277),SEARCH_DB!$P:$P,0)),""),"") | N300: =IFERROR(INDEX(SEARCH_DB!$O:$O,MATCH(ROW(A277),SEARCH_DB!$P:$P,0)),"")

Sheet SEARCH_DB
A1: 순번 | B1: 시트명 | C1: 원본행 | D1: 표시성명 | E1: 검색성명 | F1: 보증금 | G1: 입금일/결제일 | H1: 현금/카드 | I1: 수익금 | J1: 최초지급일 | K1: 계좌은행 | L1: 계좌번호 | M1: 예금주 | N1: 주민등록번호 | O1: 핸드폰번호 | P1: 검색번호
A2: 1 | B2: 1월 | C2: 3 | D2: ='1월'!B3 -> 신영미 | E2: =IF(D2<>"",D2,"") -> 신영미 | F2: ='1월'!C3 -> 10000000 | G2: ='1월'!D3 -> 2026.1.1 | H2: ='1월'!E3 -> 현금 | I2: ='1월'!F3 -> 500000 | J2: ='1월'!G3 -> 2026.3.1 | K2: ='1월'!H3 -> 농협은행 | L2: ='1월'!I3 -> 312-013-5476311 | M2: ='1월'!J3 -> 신영미 | ... O2: ='1월'!L3 -> 010-3036-9756 | P2: =IF(AND(검색!$C$4<>"",E2<>"",ISNUMBER(SEARCH(검색!$C$4,E2)),OR(D2<>"",F2<>"",G2<>"",H2<>"")),COUNT(P$1:P1)+1,"")
A3: 2 | B3: 1월 | C3: 4 | D3: ='1월'!B4 -> 최한영 | E3: =IF(D3<>"",D3,IF(B3=B2,E2,"")) -> 최한영 | F3: ='1월'!C4 -> 30000000 | G3: ='1월'!D4 -> 2026.1.2 | H3: ='1월'!E4 -> 0 | I3: ='1월'!F4 -> 2028000 | J3: ='1월'!G4 -> 2026.3.2 | K3: ='1월'!H4 -> 농협 | L3: ='1월'!I4 -> 356-0090-8343-33 | M3: ='1월'!J4 -> 한동현 | ... O3: ='1월'!L4 -> 010-3917-1399 | P3: =IF(AND(검색!$C$4<>"",E3<>"",ISNUMBER(SEARCH(검색!$C$4,E3)),OR(D3<>"",F3<>"",G3<>"",H3<>"")),COUNT(P$1:P2)+1,"")
A4: 3 | B4: 1월 | C4: 5 | D4: ='1월'!B5 -> 김정임 | E4: =IF(D4<>"",D4,IF(B4=B3,E3,"")) -> 김정임 | F4: ='1월'!C5 -> 10000000 | G4: ='1월'!D5 -> 2026.1.2 | H4: ='1월'!E5 -> 0 | I4: ='1월'!F5 -> 500000 | J4: ='1월'!G5 -> 2026.3.2 | K4: ='1월'!H5 -> 농협 | L4: ='1월'!I5 -> 356-0090-8343-33 | M4: ='1월'!J5 -> 한동현 | ... O4: ='1월'!L5 -> 010-9261-8355 | P4: =IF(AND(검색!$C$4<>"",E4<>"",ISNUMBER(SEARCH(검색!$C$4,E4)),OR(D4<>"",F4<>"",G4<>"",H4<>"")),COUNT(P$1:P3)+1,"")
A5: 4 | B5: 1월 | C5: 6 | D5: ='1월'!B6 -> 한유성 | E5: =IF(D5<>"",D5,IF(B5=B4,E4,"")) -> 한유성 | F5: ='1월'!C6 -> 30000000 | G5: ='1월'!D6 -> 2026.1.5 | H5: ='1월'!E6 -> 현금 | I5: ='1월'!F6 -> 2028000 | J5: ='1월'!G6 -> 2026.3.5 | K5: ='1월'!H6 -> 케이뱅크 | L5: ='1월'!I6 -> 100-11660-33-11 | M5: ='1월'!J6 -> 곽경호 | ... O5: ='1월'!L6 -> 010-4937-8876 | P5: =IF(AND(검색!$C$4<>"",E5<>"",ISNUMBER(SEARCH(검색!$C$4,E5)),OR(D5<>"",F5<>"",G5<>"",H5<>"")),COUNT(P$1:P4)+1,"")
A6: 5 | B6: 1월 | C6: 7 | D6: ='1월'!B7 -> 용서연 | E6: =IF(D6<>"",D6,IF(B6=B5,E5,"")) -> 용서연 | F6: ='1월'!C7 -> 10000000 | G6: ='1월'!D7 -> 2026.1.8 | H6: ='1월'!E7 -> 현금 | I6: ='1월'!F7 -> 800000 | J6: ='1월'!G7 -> 2026.3.8 | K6: ='1월'!H7 -> 농협 | L6: ='1월'!I7 -> 130012-52-237844 | M6: ='1월'!J7 -> 용서연 | ... O6: ='1월'!L7 -> 010-8285-2846 | P6: =IF(AND(검색!$C$4<>"",E6<>"",ISNUMBER(SEARCH(검색!$C$4,E6)),OR(D6<>"",F6<>"",G6<>"",H6<>"")),COUNT(P$1:P5)+1,"")
A7: 6 | B7: 1월 | C7: 8 | D7: ='1월'!B8 -> 인혜수 | E7: =IF(D7<>"",D7,IF(B7=B6,E6,"")) -> 인혜수 | F7: ='1월'!C8 -> 10000000 | G7: ='1월'!D8 -> 2026.1.8 | H7: ='1월'!E8 -> 현금 | I7: ='1월'!F8 -> 800000 | J7: ='1월'!G8 -> 2026.3.8 | K7: ='1월'!H8 -> 농협 | L7: ='1월'!I8 -> 301-3577-1592-11 | M7: ='1월'!J8 -> 이하은 | ... O7: ='1월'!L8 -> 010-9924-6058 | P7: =IF(AND(검색!$C$4<>"",E7<>"",ISNUMBER(SEARCH(검색!$C$4,E7)),OR(D7<>"",F7<>"",G7<>"",H7<>"")),COUNT(P$1:P6)+1,"")
A8: 7 | B8: 1월 | C8: 9 | D8: ='1월'!B9 -> 이세은 | E8: =IF(D8<>"",D8,IF(B8=B7,E7,"")) -> 이세은 | F8: ='1월'!C9 -> 10000000 | G8: ='1월'!D9 -> 2026.1.8 | H8: ='1월'!E9 -> 현금 | I8: ='1월'!F9 -> 800000 | J8: ='1월'!G9 -> 2026.3.8 | K8: ='1월'!H9 -> 농협 | L8: ='1월'!I9 -> 301-3577-1592-11 | M8: ='1월'!J9 -> 이하은 | ... O8: ='1월'!L9 -> 010-4742-0224 | P8: =IF(AND(검색!$C$4<>"",E8<>"",ISNUMBER(SEARCH(검색!$C$4,E8)),OR(D8<>"",F8<>"",G8<>"",H8<>"")),COUNT(P$1:P7)+1,"")
A9: 8 | B9: 1월 | C9: 10 | D9: ='1월'!B10 -> 최수호 | E9: =IF(D9<>"",D9,IF(B9=B8,E8,"")) -> 최수호 | F9: ='1월'!C10 -> 10000000 | G9: ='1월'!D10 -> 2026.1.9 | H9: ='1월'!E10 -> 현금(입금자:박명희) | I9: ='1월'!F10 -> 0 | J9: ='1월'!G10 -> 2026.3.9 | K9: ='1월'!H10 -> 국민 | L9: ='1월'!I10 -> 091-24-0230-115 | M9: ='1월'!J10 -> 박명희 | ... O9: ='1월'!L10 -> 010-8785-2273 | P9: =IF(AND(검색!$C$4<>"",E9<>"",ISNUMBER(SEARCH(검색!$C$4,E9)),OR(D9<>"",F9<>"",G9<>"",H9<>"")),COUNT(P$1:P8)+1,"")
A10: 9 | B10: 1월 | C10: 11 | D10: ='1월'!B11 -> 주하민 | E10: =IF(D10<>"",D10,IF(B10=B9,E9,"")) -> 주하민 | F10: ='1월'!C11 -> 10000000 | G10: ='1월'!D11 -> 2026.1.10 | H10: ='1월'!E11 -> 현금 | I10: ='1월'!F11 -> 800000 | J10: ='1월'!G11 -> 2026.3.10 | K10: ='1월'!H11 -> 농협 | L10: ='1월'!I11 -> 209-12-751764 | M10: ='1월'!J11 -> 엄혜란 | ... O10: ='1월'!L11 -> 010-4506-5645 | P10: =IF(AND(검색!$C$4<>"",E10<>"",ISNUMBER(SEARCH(검색!$C$4,E10)),OR(D10<>"",F10<>"",G10<>"",H10<>"")),COUNT(P$1:P9)+1,"")
A11: 10 | B11: 1월 | C11: 12 | D11: ='1월'!B12 -> 한리나 | E11: =IF(D11<>"",D11,IF(B11=B10,E10,"")) -> 한리나 | F11: ='1월'!C12 -> 10000000 | G11: ='1월'!D12 -> 2026.1.10 | H11: ='1월'!E12 -> 현금 | I11: ='1월'!F12 -> 800000 | J11: ='1월'!G12 -> 2026.3.10 | K11: ='1월'!H12 -> 농협 | L11: ='1월'!I12 -> 302-1092-2478-81 | M11: ='1월'!J12 -> 한리나 | ... O11: ='1월'!L12 -> 010-3383-6172 | P11: =IF(AND(검색!$C$4<>"",E11<>"",ISNUMBER(SEARCH(검색!$C$4,E11)),OR(D11<>"",F11<>"",G11<>"",H11<>"")),COUNT(P$1:P10)+1,"")
A12: 11 | B12: 1월 | C12: 13 | D12: ='1월'!B13 -> 박란 | E12: =IF(D12<>"",D12,IF(B12=B11,E11,"")) -> 박란 | F12: ='1월'!C13 -> 1000000 | G12: ='1월'!D13 -> 2025.12.11 | H12: ='1월'!E13 -> 현금 | I12: ='1월'!F13 -> 0 | J12: ='1월'!G13 -> 2026.3.11 | K12: ='1월'!H13 -> 국민 | L12: ='1월'!I13 -> 5825-020104-9618 | M12: ='1월'!J13 -> 박 란 | ... O12: ='1월'!L13 -> 010-4277-0255 | P12: =IF(AND(검색!$C$4<>"",E12<>"",ISNUMBER(SEARCH(검색!$C$4,E12)),OR(D12<>"",F12<>"",G12<>"",H12<>"")),COUNT(P$1:P11)+1,"")
A13: 12 | B13: 1월 | C13: 14 | D13: ='1월'!B14 -> 0 | E13: =IF(D13<>"",D13,IF(B13=B12,E12,"")) -> 0 | F13: ='1월'!C14 -> 9000000 | G13: ='1월'!D14 -> 2026.1.11 | H13: ='1월'!E14 -> 현금 | I13: ='1월'!F14 -> 0 | J13: ='1월'!G14 -> 0 | K13: ='1월'!H14 -> 0 | L13: ='1월'!I14 -> 0 | M13: ='1월'!J14 -> 0 | ... O13: ='1월'!L14 -> 0 | P13: =IF(AND(검색!$C$4<>"",E13<>"",ISNUMBER(SEARCH(검색!$C$4,E13)),OR(D13<>"",F13<>"",G13<>"",H13<>"")),COUNT(P$1:P12)+1,"")
A14: 13 | B14: 1월 | C14: 15 | D14: ='1월'!B15 -> 0 | E14: =IF(D14<>"",D14,IF(B14=B13,E13,"")) -> 0 | F14: ='1월'!C15 -> 10000000 | G14: ='1월'!D15 -> 2026.2.8 | H14: ='1월'!E15 -> 현금(증액) | I14: ='1월'!F15 -> 0 | J14: ='1월'!G15 -> 0 | K14: ='1월'!H15 -> 0 | L14: ='1월'!I15 -> 0 | M14: ='1월'!J15 -> 0 | ... O14: ='1월'!L15 -> 0 | P14: =IF(AND(검색!$C$4<>"",E14<>"",ISNUMBER(SEARCH(검색!$C$4,E14)),OR(D14<>"",F14<>"",G14<>"",H14<>"")),COUNT(P$1:P13)+1,"")
... A999: 998 | B999: 1월 | C999: 1000 | D999: ='1월'!B1000 -> 0 | E999: =IF(D999<>"",D999,IF(B999=B998,E998,"")) -> 0 | F999: ='1월'!C1000 -> 0 | G999: ='1월'!D1000 -> 0 | H999: ='1월'!E1000 -> 0 | I999: ='1월'!F1000 -> 0 | J999: ='1월'!G1000 -> 0 | K999: ='1월'!H1000 -> 0 | L999: ='1월'!I1000 -> 0 | M999: ='1월'!J1000 -> 0 | ... O999: ='1월'!L1000 -> 0 | P999: =IF(AND(검색!$C$4<>"",E999<>"",ISNUMBER(SEARCH(검색!$C$4,E999)),OR(D999<>"",F999<>"",G999<>"",H999<>"")),COUNT(P$1:P998)+1,"")
A1000: 999 | B1000: 2월 | C1000: 3 | D1000: ='2월'!B3 -> 구재영 | E1000: =IF(D1000<>"",D1000,IF(B1000=B999,E999,"")) -> 구재영 | F1000: ='2월'!C3 -> 10000000 | G1000: ='2월'!D3 -> 2026.2.1 | H1000: ='2월'!E3 -> 현금 | I1000: ='2월'!F3 -> 800000 | J1000: ='2월'!G3 -> 2026.4.1 | K1000: ='2월'!H3 -> 농협 | L1000: ='2월'!I3 -> 352-1407-036993 | M1000: ='2월'!J3 -> 구재영 | ... O1000: ='2월'!L3 -> 010-3847-1216 | P1000: =IF(AND(검색!$C$4<>"",E1000<>"",ISNUMBER(SEARCH(검색!$C$4,E1000)),OR(D1000<>"",F1000<>"",G1000<>"",H1000<>"")),COUNT(P$1:P999)+1,"")
